{"channel":"l2_data","timestamp":"2026-07-30T15:17:56.048551738Z","sequence_num":0,"events":[{"type":"snapshot","product_id":"BTC-USD","updates":[{"side":"bid","event_time":"2026-07-30T15:17:55.683286Z","price_level":"64651.67","new_quantity":"0.23826919"},{"side":"bid","event_time":"2026-07-30T15:17:55.683286Z","price_level":"64651.35","new_quantity":"0.00225418"},{"side":"bid","event_time":"2026-07-30T15:17:55.683286Z","price_level":"64650.92","new_quantity":"0.000018"},{"side":"bid","event_time":"2026-07-30T15:17:55.683286Z","price_level":"64650.61","new_quantity":"0.01546776"},{"side":"bid","event_time":"2026-07-30T15:17:55.683286Z","price_level":"64647.83","new_quantity":"0.04"},{"side":"bid","event_time":"2026-07-30T15:17:55.683286Z","price_level":"64647.82","new_quantity":"0.72566046"},{"side":"bid","event_time":"2026-07-30T15:17:55.683286Z","price_level":"64647.81","new_quantity":"0.30892886"},{"side":"bid","event_time":"2026-07-30T15:17:55.683286Z","price_level":"64647.79","new_quantity":"0.18478583"},{"side":"bid","event_time":"2026-07-30T15:17:55.683286Z","price_level":"64647.61","new_quantity":"0.000018"},{"side":"bid","event_time":"2026-07-30T15:17:55.683286Z","price_level":"64646.82","new_quantity":"0.01546866"},{"side":"bid","event_time":"2026-07-30T15:17:55.683286Z","price_level":"64646","new_quantity":"0.5"},{"side":"bid","event_time":"2026-07-30T15:17:55.683286Z","price_level":"64645.61","new_quantity":"0.30892886"},{"side":"bid","event_time":"2026-07-30T15:17:55.683286Z","price_level":"64645.2","new_quantity":"0.01546906"},{"side":"bid","event_time":"2026-07-30T15:17:55.683286Z","price_level":"64645.02","new_quantity":"1.77690556"},{"side":"bid","event_time":"2026-07-30T15:17:55.683286Z","price_level":"64645.01","new_quantity":"0.1687"},{"side":"bid","event_time":"2026-07-30T15:17:55.683286Z","price_level":"64645","new_quantity":"1.01"},{"side":"bid","event_time":"2026-07-30T15:17:55.683286Z","price_level":"64644.44","new_quantity":"0.16676"},{"side":"bid","event_time":"2026-07-30T15:17:55.683286Z","price_level":"64644.3","new_quantity":"0.000018"},{"side":"bid","event_time":"2026-07-30T15:17:55.683286Z","price_level":"64643","new_quantity":"0.12375661"},{"side":"bid","event_time":"2026-07-30T15:17:55.683286Z","price_level":"64642.55","new_quantity":"0.30892886"},{"side":"bid","event_time":"2026-07-30T15:17:55.683286Z","price_level":"64642.49","new_quantity":"0.0769941"},{"side":"bid","event_time":"2026-07-30T15:17:55.683286Z","price_level":"64642.29","new_quantity":"0.18478583"},{"side":"bid","event_time":"2026-07-30T15:17:55.683286Z","price_level":"64642","new_quantity":"1.5"},{"side":"bid","event_time":"2026-07-30T15:17:55.683286Z","price_level":"64641.97","new_quantity":"0.00116005"},{"side":"bid","event_time":"2026-07-30T15:17:55.683286Z","price_level":"64641.36","new_quantity":"0.12375977"},{"side":"bid","event_time":"2026-07-30T15:17:55.683286Z","price_level":"64641.02","new_quantity":"0.00772332"},{"side":"bid","event_time":"2026-07-30T15:17:55.683286Z","price_level":"64641.01","new_quantity":"1.14271986"},{"side":"bid","event_time":"2026-07-30T15:17:55.683286Z","price_level":"64641","new_quantity":"1"},{"side":"bid","event_time":"2026-07-30T15:17:55.683286Z","price_level":"64640.99","new_quantity":"0.0010356"},{"side":"bid","event_time":"2026-07-30T15:17:55.683286Z","price_level":"64640","new_quantity":"1.01"},{"side":"bid","event_time":"2026-07-30T15:17:55.683286Z","price_level":"64639.25","new_quantity":"0.00150724"},{"side":"bid","event_time":"2026-07-30T15:17:55.683286Z","price_level":"64639.08","new_quantity":"0.05523726"},{"side":"bid","event_time":"2026-07-30T15:17:55.683286Z","price_level":"64638.62","new_quantity":"0.06"},{"side":"bid","event_time":"2026-07-30T15:17:55.683286Z","price_level":"64637.68","new_quantity":"0.000018"},{"side":"bid","event_time":"2026-07-30T15:17:55.683286Z","price_level":"64637.14","new_quantity":"0.0769941"},{"side":"bid","event_time":"2026-07-30T15:17:55.683286Z","price_level":"64637.12","new_quantity":"1.32949296"},{"side":"bid","event_time":"2026-07-30T15:17:55.683286Z","price_level":"64637.11","new_quantity":"0.18478583"},{"side":"bid","event_time":"2026-07-30T15:17:55.683286Z","price_level":"64637","new_quantity":"0.5"},{"side":"bid","event_time":"2026-07-30T15:17:55.683286Z","price_level":"64636.4","new_quantity":"0.038725"},{"side":"bid","event_time":"2026-07-30T15:17:55.683286Z","price_level":"64636","new_quantity":"1.00150724"},{"side":"offer","event_time":"2026-07-30T15:17:55.683286Z","price_level":"64651.68","new_quantity":"0.03735172"},{"side":"offer","event_time":"2026-07-30T15:17:55.683286Z","price_level":"64651.91","new_quantity":"0.12320962"},{"side":"offer","event_time":"2026-07-30T15:17:55.683286Z","price_level":"64653","new_quantity":"0.0164"},{"side":"offer","event_time":"2026-07-30T15:17:55.683286Z","price_level":"64653.22","new_quantity":"0.51546713"},{"side":"offer","event_time":"2026-07-30T15:17:55.683286Z","price_level":"64653.3","new_quantity":"0.00773375"},{"side":"offer","event_time":"2026-07-30T15:17:55.683286Z","price_level":"64653.43","new_quantity":"0.12373666"},{"side":"offer","event_time":"2026-07-30T15:17:55.683286Z","price_level":"64655.48","new_quantity":"0.00966718"},{"side":"offer","event_time":"2026-07-30T15:17:55.683286Z","price_level":"64657.96","new_quantity":"0.24867398"},{"side":"offer","event_time":"2026-07-30T15:17:55.683286Z","price_level":"64659.12","new_quantity":"0.01420656"},{"side":"offer","event_time":"2026-07-30T15:17:55.683286Z","price_level":"64660.44","new_quantity":"0.00772332"},{"side":"offer","event_time":"2026-07-30T15:17:55.683286Z","price_level":"64660.45","new_quantity":"0.00009666"},{"side":"offer","event_time":"2026-07-30T15:17:55.683286Z","price_level":"64660.82","new_quantity":"0.30892886"},{"side":"offer","event_time":"2026-07-30T15:17:55.683286Z","price_level":"64660.85","new_quantity":"0.000018"},{"side":"offer","event_time":"2026-07-30T15:17:55.683286Z","price_level":"64661.35","new_quantity":"0.00811922"},{"side":"offer","event_time":"2026-07-30T15:17:55.683286Z","price_level":"64661.42","new_quantity":"0.00773259"},{"side":"offer","event_time":"2026-07-30T15:17:55.683286Z","price_level":"64661.69","new_quantity":"0.00009666"},{"side":"offer","event_time":"2026-07-30T15:17:55.683286Z","price_level":"64661.75","new_quantity":"0.32644783"},{"side":"offer","event_time":"2026-07-30T15:17:55.683286Z","price_level":"64661.82","new_quantity":"0.00002321"},{"side":"offer","event_time":"2026-07-30T15:17:55.683286Z","price_level":"64662","new_quantity":"0.00150724"},{"side":"offer","event_time":"2026-07-30T15:17:55.683286Z","price_level":"64662.15","new_quantity":"0.00116005"},{"side":"offer","event_time":"2026-07-30T15:17:55.683286Z","price_level":"64662.37","new_quantity":"0.18478583"},{"side":"offer","event_time":"2026-07-30T15:17:55.683286Z","price_level":"64662.84","new_quantity":"0.30892886"},{"side":"offer","event_time":"2026-07-30T15:17:55.683286Z","price_level":"64662.95","new_quantity":"0.00811902"},{"side":"offer","event_time":"2026-07-30T15:17:55.683286Z","price_level":"64662.98","new_quantity":"0.0077324"},{"side":"offer","event_time":"2026-07-30T15:17:55.683286Z","price_level":"64663.12","new_quantity":"0.0769941"},{"side":"offer","event_time":"2026-07-30T15:17:55.683286Z","price_level":"64663.13","new_quantity":"0.1687"},{"side":"offer","event_time":"2026-07-30T15:17:55.683286Z","price_level":"64664.16","new_quantity":"0.000018"},{"side":"offer","event_time":"2026-07-30T15:17:55.683286Z","price_level":"64664.77","new_quantity":"0.32644783"},{"side":"offer","event_time":"2026-07-30T15:17:55.683286Z","price_level":"64664.78","new_quantity":"0.30892886"},{"side":"offer","event_time":"2026-07-30T15:17:55.683286Z","price_level":"64665","new_quantity":"0.01"},{"side":"offer","event_time":"2026-07-30T15:17:55.683286Z","price_level":"64665.25","new_quantity":"0.00150724"},{"side":"offer","event_time":"2026-07-30T15:17:55.683286Z","price_level":"64666.9","new_quantity":"0.30892886"},{"side":"offer","event_time":"2026-07-30T15:17:55.683286Z","price_level":"64667.47","new_quantity":"0.000018"},{"side":"offer","event_time":"2026-07-30T15:17:55.683286Z","price_level":"64668","new_quantity":"1"},{"side":"offer","event_time":"2026-07-30T15:17:55.683286Z","price_level":"64668.16","new_quantity":"0.05927313"},{"side":"offer","event_time":"2026-07-30T15:17:55.683286Z","price_level":"64668.5","new_quantity":"0.00150724"},{"side":"offer","event_time":"2026-07-30T15:17:55.683286Z","price_level":"64668.78","new_quantity":"0.0769941"},{"side":"offer","event_time":"2026-07-30T15:17:55.683286Z","price_level":"64668.79","new_quantity":"0.05783534"},{"side":"offer","event_time":"2026-07-30T15:17:55.683286Z","price_level":"64668.82","new_quantity":"0.18478583"},{"side":"offer","event_time":"2026-07-30T15:17:55.683286Z","price_level":"64669","new_quantity":"0.5"}]}]}
{"channel":"l2_data","timestamp":"2026-07-30T15:17:56.076075332Z","sequence_num":1,"events":[{"type":"update","product_id":"BTC-USD","updates":[{"side":"bid","event_time":"2026-07-30T15:17:55.739625Z","price_level":"64651.67","new_quantity":"0.06956919"},{"side":"bid","event_time":"2026-07-30T15:17:55.739625Z","price_level":"64603.57","new_quantity":"0.89344666"},{"side":"bid","event_time":"2026-07-30T15:17:55.739625Z","price_level":"64603.56","new_quantity":"2.18378601"},{"side":"bid","event_time":"2026-07-30T15:17:55.739625Z","price_level":"64603.55","new_quantity":"0"},{"side":"bid","event_time":"2026-07-30T15:17:55.739625Z","price_level":"64603.54","new_quantity":"0"},{"side":"offer","event_time":"2026-07-30T15:17:55.739625Z","price_level":"64658.7","new_quantity":"0.30892886"},{"side":"offer","event_time":"2026-07-30T15:17:55.739625Z","price_level":"64661.75","new_quantity":"0.65289566"},{"side":"offer","event_time":"2026-07-30T15:17:55.739625Z","price_level":"64662.46","new_quantity":"0.628755"},{"side":"offer","event_time":"2026-07-30T15:17:55.739625Z","price_level":"64672.99","new_quantity":"0.50290867"},{"side":"offer","event_time":"2026-07-30T15:17:55.739625Z","price_level":"64674.05","new_quantity":"0"},{"side":"offer","event_time":"2026-07-30T15:17:55.739625Z","price_level":"64838.52","new_quantity":"2.94899141"}]}]}
{"channel":"l2_data","timestamp":"2026-07-30T15:17:56.077818726Z","sequence_num":2,"events":[{"type":"update","product_id":"BTC-USD","updates":[{"side":"offer","event_time":"2026-07-30T15:17:55.7582Z","price_level":"64661.75","new_quantity":"0.32644783"},{"side":"offer","event_time":"2026-07-30T15:17:55.7582Z","price_level":"64662.46","new_quantity":"0"}]}]}
{"channel":"l2_data","timestamp":"2026-07-30T15:17:56.081494152Z","sequence_num":3,"events":[{"type":"update","product_id":"BTC-USD","updates":[{"side":"bid","event_time":"2026-07-30T15:17:55.827959Z","price_level":"64651.67","new_quantity":"0.23826919"},{"side":"bid","event_time":"2026-07-30T15:17:55.827959Z","price_level":"64647.83","new_quantity":"0.1169941"},{"side":"bid","event_time":"2026-07-30T15:17:55.827959Z","price_level":"64647.19","new_quantity":"0.1237486"},{"side":"bid","event_time":"2026-07-30T15:17:55.827959Z","price_level":"64643.51","new_quantity":"0.15469455"},{"side":"bid","event_time":"2026-07-30T15:17:55.827959Z","price_level":"64643","new_quantity":"0"},{"side":"bid","event_time":"2026-07-30T15:17:55.827959Z","price_level":"64641.36","new_quantity":"0"},{"side":"bid","event_time":"2026-07-30T15:17:55.827959Z","price_level":"64641.02","new_quantity":"0.00772332"},{"side":"bid","event_time":"2026-07-30T15:17:55.827959Z","price_level":"64640.01","new_quantity":"0.30892886"},{"side":"bid","event_time":"2026-07-30T15:17:55.827959Z","price_level":"64637.04","new_quantity":"0.5"},{"side":"bid","event_time":"2026-07-30T15:17:55.827959Z","price_level":"64628.95","new_quantity":"0.60372678"},{"side":"bid","event_time":"2026-07-30T15:17:55.827959Z","price_level":"64628.94","new_quantity":"0.64965991"},{"side":"bid","event_time":"2026-07-30T15:17:55.827959Z","price_level":"64628.93","new_quantity":"0"},{"side":"bid","event_time":"2026-07-30T15:17:55.827959Z","price_level":"64624.56","new_quantity":"0"},{"side":"bid","event_time":"2026-07-30T15:17:55.827959Z","price_level":"64624.55","new_quantity":"0"},{"side":"bid","event_time":"2026-07-30T15:17:55.827959Z","price_level":"64602.4","new_quantity":"0.5"},{"side":"bid","event_time":"2026-07-30T15:17:55.827959Z","price_level":"64500.18","new_quantity":"0"},{"side":"bid","event_time":"2026-07-30T15:17:55.827959Z","price_level":"56570.22","new_quantity":"0.01324455"},{"side":"offer","event_time":"2026-07-30T15:17:55.827959Z","price_level":"64651.91","new_quantity":"0"},{"side":"offer","event_time":"2026-07-30T15:17:55.827959Z","price_level":"64653.43","new_quantity":"0"},{"side":"offer","event_time":"2026-07-30T15:17:55.827959Z","price_level":"64655.62","new_quantity":"0"},{"side":"offer","event_time":"2026-07-30T15:17:55.827959Z","price_level":"64655.65","new_quantity":"0.12373242"},{"side":"offer","event_time":"2026-07-30T15:17:55.827959Z","price_level":"64658.7","new_quantity":"0"},{"side":"offer","event_time":"2026-07-30T15:17:55.827959Z","price_level":"64661.75","new_quantity":"0"},{"side":"offer","event_time":"2026-07-30T15:17:55.827959Z","price_level":"64663.12","new_quantity":"0"},{"side":"offer","event_time":"2026-07-30T15:17:55.827959Z","price_level":"64668","new_quantity":"0"},{"side":"offer","event_time":"2026-07-30T15:17:55.827959Z","price_level":"64668.99","new_quantity":"0.65289566"},{"side":"offer","event_time":"2026-07-30T15:17:55.827959Z","price_level":"64669.6","new_quantity":"0"},{"side":"offer","event_time":"2026-07-30T15:17:55.827959Z","price_level":"64672.99","new_quantity":"0.32644783"},{"side":"offer","event_time":"2026-07-30T15:17:55.827959Z","price_level":"64673.99","new_quantity":"0"},{"side":"offer","event_time":"2026-07-30T15:17:55.827959Z","price_level":"64674.98","new_quantity":"0.1803432"},{"side":"offer","event_time":"2026-07-30T15:17:55.827959Z","price_level":"64685.3","new_quantity":"0"},{"side":"offer","event_time":"2026-07-30T15:17:55.827959Z","price_level":"64711.74","new_quantity":"0"}]}]}
{"channel":"l2_data","timestamp":"2026-07-30T15:17:56.083375522Z","sequence_num":4,"events":[{"type":"update","product_id":"BTC-USD","updates":[{"side":"bid","event_time":"2026-07-30T15:17:55.87926Z","price_level":"64648.03","new_quantity":"0.12374698"},{"side":"bid","event_time":"2026-07-30T15:17:55.87926Z","price_level":"64648.01","new_quantity":"2.26600309"},{"side":"bid","event_time":"2026-07-30T15:17:55.87926Z","price_level":"64648","new_quantity":"0.5"},{"side":"bid","event_time":"2026-07-30T15:17:55.87926Z","price_level":"64647.82","new_quantity":"0"},{"side":"bid","event_time":"2026-07-30T15:17:55.87926Z","price_level":"64647","new_quantity":"1"},{"side":"bid","event_time":"2026-07-30T15:17:55.87926Z","price_level":"64646","new_quantity":"1.5"},{"side":"bid","event_time":"2026-07-30T15:17:55.87926Z","price_level":"64645","new_quantity":"0.01"},{"side":"bid","event_time":"2026-07-30T15:17:55.87926Z","price_level":"64643.51","new_quantity":"0"},{"side":"bid","event_time":"2026-07-30T15:17:55.87926Z","price_level":"64642.56","new_quantity":"0.00772332"},{"side":"bid","event_time":"2026-07-30T15:17:55.87926Z","price_level":"64641.02","new_quantity":"0"},{"side":"bid","event_time":"2026-07-30T15:17:55.87926Z","price_level":"64637.12","new_quantity":"0.30892886"},{"side":"bid","event_time":"2026-07-30T15:17:55.87926Z","price_level":"64636","new_quantity":"0.00150724"},{"side":"bid","event_time":"2026-07-30T15:17:55.87926Z","price_level":"64622.96","new_quantity":"0.00154496"},{"side":"bid","event_time":"2026-07-30T15:17:55.87926Z","price_level":"64620.69","new_quantity":"0"},{"side":"bid","event_time":"2026-07-30T15:17:55.87926Z","price_level":"64616.5","new_quantity":"0.00923204"},{"side":"bid","event_time":"2026-07-30T15:17:55.87926Z","price_level":"64616.01","new_quantity":"0"},{"side":"bid","event_time":"2026-07-30T15:17:55.87926Z","price_level":"64616","new_quantity":"0"},{"side":"bid","event_time":"2026-07-30T15:17:55.87926Z","price_level":"64614.23","new_quantity":"0"},{"side":"bid","event_time":"2026-07-30T15:17:55.87926Z","price_level":"64603.59","new_quantity":"0.89344638"},{"side":"bid","event_time":"2026-07-30T15:17:55.87926Z","price_level":"64603.58","new_quantity":"2.18378534"},{"side":"bid","event_time":"2026-07-30T15:17:55.87926Z","price_level":"64603.57","new_quantity":"0"},{"side":"bid","event_time":"2026-07-30T15:17:55.87926Z","price_level":"64603.56","new_quantity":"0"},{"side":"offer","event_time":"2026-07-30T15:17:55.87926Z","price_level":"64657.83","new_quantity":"0.15466031"},{"side":"offer","event_time":"2026-07-30T15:17:55.87926Z","price_level":"64660.44","new_quantity":"0"},{"side":"offer","event_time":"2026-07-30T15:17:55.87926Z","price_level":"64664.15","new_quantity":"0.00643592"},{"side":"offer","event_time":"2026-07-30T15:17:55.87926Z","price_level":"64668.99","new_quantity":"0"},{"side":"offer","event_time":"2026-07-30T15:17:55.87926Z","price_level":"64669.05","new_quantity":"0"},{"side":"offer","event_time":"2026-07-30T15:17:55.87926Z","price_level":"64672.99","new_quantity":"0.32644783"},{"side":"offer","event_time":"2026-07-30T15:17:55.87926Z","price_level":"64674.98","new_quantity":"0"},{"side":"offer","event_time":"2026-07-30T15:17:55.87926Z","price_level":"64675.74","new_quantity":"0.1803432"},{"side":"offer","event_time":"2026-07-30T15:17:55.87926Z","price_level":"64675.96","new_quantity":"0.017313"}]}]}
{"channel":"l2_data","timestamp":"2026-07-30T15:17:56.088004566Z","sequence_num":5,"events":[{"type":"update","product_id":"BTC-USD","updates":[{"side":"bid","event_time":"2026-07-30T15:17:55.914342Z","price_level":"64637.13","new_quantity":"0.94202923"},{"side":"bid","event_time":"2026-07-30T15:17:55.914342Z","price_level":"64625.16","new_quantity":"0.0015449"},{"side":"bid","event_time":"2026-07-30T15:17:55.914342Z","price_level":"64622.96","new_quantity":"0"},{"side":"bid","event_time":"2026-07-30T15:17:55.914342Z","price_level":"64618.71","new_quantity":"0.00772454"},{"side":"bid","event_time":"2026-07-30T15:17:55.914342Z","price_level":"64616.5","new_quantity":"0.00150724"},{"side":"bid","event_time":"2026-07-30T15:17:55.914342Z","price_level":"64553.86","new_quantity":"0"},{"side":"bid","event_time":"2026-07-30T15:17:55.914342Z","price_level":"64553.85","new_quantity":"0"},{"side":"bid","event_time":"2026-07-30T15:17:55.914342Z","price_level":"64466.73","new_quantity":"2.93641679"},{"side":"bid","event_time":"2026-07-30T15:17:55.914342Z","price_level":"56570.22","new_quantity":"0"},{"side":"offer","event_time":"2026-07-30T15:17:55.914342Z","price_level":"64657.96","new_quantity":"0.00005261"},{"side":"offer","event_time":"2026-07-30T15:17:55.914342Z","price_level":"64664.15","new_quantity":"0"},{"side":"offer","event_time":"2026-07-30T15:17:55.914342Z","price_level":"64669","new_quantity":"1.5"},{"side":"offer","event_time":"2026-07-30T15:17:55.914342Z","price_level":"64673.99","new_quantity":"0.1803432"},{"side":"offer","event_time":"2026-07-30T15:17:55.914342Z","price_level":"64675.74","new_quantity":"0"}]}]}
{"channel":"l2_data","timestamp":"2026-07-30T15:17:56.091210075Z","sequence_num":6,"events":[{"type":"update","product_id":"BTC-USD","updates":[{"side":"bid","event_time":"2026-07-30T15:17:55.971918Z","price_level":"64635.01","new_quantity":"0.00583"},{"side":"bid","event_time":"2026-07-30T15:17:55.971918Z","price_level":"64603.61","new_quantity":"0.8934461"},{"side":"bid","event_time":"2026-07-30T15:17:55.971918Z","price_level":"64603.6","new_quantity":"2.18378466"},{"side":"bid","event_time":"2026-07-30T15:17:55.971918Z","price_level":"64603.59","new_quantity":"0"},{"side":"bid","event_time":"2026-07-30T15:17:55.971918Z","price_level":"64603.58","new_quantity":"0"},{"side":"bid","event_time":"2026-07-30T15:17:55.971918Z","price_level":"63134","new_quantity":"0.00583"},{"side":"bid","event_time":"2026-07-30T15:17:55.971918Z","price_level":"63132.44","new_quantity":"0"},{"side":"offer","event_time":"2026-07-30T15:17:55.971918Z","price_level":"64653","new_quantity":"0"},{"side":"offer","event_time":"2026-07-30T15:17:55.971918Z","price_level":"64664.76","new_quantity":"0.00613021"},{"side":"offer","event_time":"2026-07-30T15:17:55.971918Z","price_level":"64668.81","new_quantity":"0.32644783"},{"side":"offer","event_time":"2026-07-30T15:17:55.971918Z","price_level":"64668.98","new_quantity":"0.65289566"},{"side":"offer","event_time":"2026-07-30T15:17:55.971918Z","price_level":"64669","new_quantity":"0.5"},{"side":"offer","event_time":"2026-07-30T15:17:55.971918Z","price_level":"64672.99","new_quantity":"0.50679103"},{"side":"offer","event_time":"2026-07-30T15:17:55.971918Z","price_level":"64673.99","new_quantity":"0"},{"side":"offer","event_time":"2026-07-30T15:17:55.971918Z","price_level":"64680","new_quantity":"1.01"},{"side":"offer","event_time":"2026-07-30T15:17:55.971918Z","price_level":"64686.66","new_quantity":"0.15459283"},{"side":"offer","event_time":"2026-07-30T15:17:55.971918Z","price_level":"65747.89","new_quantity":"0.00583"}]}]}
{"channel":"l2_data","timestamp":"2026-07-30T15:17:56.093189281Z","sequence_num":7,"events":[{"type":"update","product_id":"BTC-USD","updates":[{"side":"bid","event_time":"2026-07-30T15:17:56.031627Z","price_level":"64646.82","new_quantity":"0.00773433"},{"side":"bid","event_time":"2026-07-30T15:17:56.031627Z","price_level":"64645.2","new_quantity":"0.00773453"},{"side":"offer","event_time":"2026-07-30T15:17:56.031627Z","price_level":"64660.45","new_quantity":"0"},{"side":"offer","event_time":"2026-07-30T15:17:56.031627Z","price_level":"64661.42","new_quantity":"0"},{"side":"offer","event_time":"2026-07-30T15:17:56.031627Z","price_level":"64661.69","new_quantity":"0"},{"side":"offer","event_time":"2026-07-30T15:17:56.031627Z","price_level":"64662.98","new_quantity":"0"},{"side":"offer","event_time":"2026-07-30T15:17:56.031627Z","price_level":"64663.03","new_quantity":"0"},{"side":"offer","event_time":"2026-07-30T15:17:56.031627Z","price_level":"64668.79","new_quantity":"0.05783534"},{"side":"offer","event_time":"2026-07-30T15:17:56.031627Z","price_level":"64668.81","new_quantity":"0"},{"side":"offer","event_time":"2026-07-30T15:17:56.031627Z","price_level":"64668.98","new_quantity":"0"},{"side":"offer","event_time":"2026-07-30T15:17:56.031627Z","price_level":"64671","new_quantity":"1"},{"side":"offer","event_time":"2026-07-30T15:17:56.031627Z","price_level":"64671.86","new_quantity":"0"},{"side":"offer","event_time":"2026-07-30T15:17:56.031627Z","price_level":"64672","new_quantity":"1"},{"side":"offer","event_time":"2026-07-30T15:17:56.031627Z","price_level":"64672.98","new_quantity":"0.1803432"},{"side":"offer","event_time":"2026-07-30T15:17:56.031627Z","price_level":"64672.99","new_quantity":"0.32644783"},{"side":"offer","event_time":"2026-07-30T15:17:56.031627Z","price_level":"65747.85","new_quantity":"0.00583"},{"side":"offer","event_time":"2026-07-30T15:17:56.031627Z","price_level":"65747.89","new_quantity":"0"}]}]}
{"channel":"l2_data","timestamp":"2026-07-30T15:17:56.184177183Z","sequence_num":8,"events":[{"type":"update","product_id":"BTC-USD","updates":[{"side":"bid","event_time":"2026-07-30T15:17:56.081167Z","price_level":"64651.67","new_quantity":"0.25407352"},{"side":"bid","event_time":"2026-07-30T15:17:56.081167Z","price_level":"64650.05","new_quantity":"0.00773375"},{"side":"bid","event_time":"2026-07-30T15:17:56.081167Z","price_level":"64648.04","new_quantity":"0.04"},{"side":"bid","event_time":"2026-07-30T15:17:56.081167Z","price_level":"64648.03","new_quantity":"0"},{"side":"bid","event_time":"2026-07-30T15:17:56.081167Z","price_level":"64647.87","new_quantity":"0.00966718"},{"side":"bid","event_time":"2026-07-30T15:17:56.081167Z","price_level":"64647.83","new_quantity":"0.0769941"},{"side":"bid","event_time":"2026-07-30T15:17:56.081167Z","price_level":"64644.51","new_quantity":"0.15469215"},{"side":"bid","event_time":"2026-07-30T15:17:56.081167Z","price_level":"64635.64","new_quantity":"0.00583"},{"side":"bid","event_time":"2026-07-30T15:17:56.081167Z","price_level":"64635.16","new_quantity":"0"},{"side":"bid","event_time":"2026-07-30T15:17:56.081167Z","price_level":"64635.01","new_quantity":"0"},{"side":"bid","event_time":"2026-07-30T15:17:56.081167Z","price_level":"64633.91","new_quantity":"0"},{"side":"bid","event_time":"2026-07-30T15:17:56.081167Z","price_level":"64632.29","new_quantity":"0"},{"side":"bid","event_time":"2026-07-30T15:17:56.081167Z","price_level":"64630.01","new_quantity":"0.64964964"},{"side":"bid","event_time":"2026-07-30T15:17:56.081167Z","price_level":"64628.96","new_quantity":"0"},{"side":"bid","event_time":"2026-07-30T15:17:56.081167Z","price_level":"64628.94","new_quantity":"0"},{"side":"bid","event_time":"2026-07-30T15:17:56.081167Z","price_level":"64628.92","new_quantity":"0"},{"side":"bid","event_time":"2026-07-30T15:17:56.081167Z","price_level":"64623.06","new_quantity":"0"},{"side":"bid","event_time":"2026-07-30T15:17:56.081167Z","price_level":"64603.63","new_quantity":"0.89344583"},{"side":"bid","event_time":"2026-07-30T15:17:56.081167Z","price_level":"64603.62","new_quantity":"2.18378399"},{"side":"bid","event_time":"2026-07-30T15:17:56.081167Z","price_level":"64603.61","new_quantity":"0"},{"side":"bid","event_time":"2026-07-30T15:17:56.081167Z","price_level":"64603.6","new_quantity":"0"},{"side":"bid","event_time":"2026-07-30T15:17:56.081167Z","price_level":"64585.2","new_quantity":"1.33972262"},{"side":"bid","event_time":"2026-07-30T15:17:56.081167Z","price_level":"64585.18","new_quantity":"0"},{"side":"bid","event_time":"2026-07-30T15:17:56.081167Z","price_level":"64561.7","new_quantity":"0"},{"side":"bid","event_time":"2026-07-30T15:17:56.081167Z","price_level":"64557.68","new_quantity":"0"},{"side":"bid","event_time":"2026-07-30T15:17:56.081167Z","price_level":"64551.52","new_quantity":"0"},{"side":"bid","event_time":"2026-07-30T15:17:56.081167Z","price_level":"64420.65","new_quantity":"0.00583"},{"side":"bid","event_time":"2026-07-30T15:17:56.081167Z","price_level":"63134","new_quantity":"0"},{"side":"offer","event_time":"2026-07-30T15:17:56.081167Z","price_level":"64651.68","new_quantity":"0.02961797"},{"side":"offer","event_time":"2026-07-30T15:17:56.081167Z","price_level":"64651.92","new_quantity":"0.24962137"},{"side":"offer","event_time":"2026-07-30T15:17:56.081167Z","price_level":"64653.3","new_quantity":"0"},{"side":"offer","event_time":"2026-07-30T15:17:56.081167Z","price_level":"64654.98","new_quantity":"0.1237337"},{"side":"offer","event_time":"2026-07-30T15:17:56.081167Z","price_level":"64655.48","new_quantity":"0"},{"side":"offer","event_time":"2026-07-30T15:17:56.081167Z","price_level":"64655.65","new_quantity":"0"},{"side":"offer","event_time":"2026-07-30T15:17:56.081167Z","price_level":"64664.15","new_quantity":"0.00613016"},{"side":"offer","event_time":"2026-07-30T15:17:56.081167Z","price_level":"64664.76","new_quantity":"0"},{"side":"offer","event_time":"2026-07-30T15:17:56.081167Z","price_level":"64669.01","new_quantity":"0"},{"side":"offer","event_time":"2026-07-30T15:17:56.081167Z","price_level":"64691.3","new_quantity":"0.45133384"},{"side":"offer","event_time":"2026-07-30T15:17:56.081167Z","price_level":"64693.21","new_quantity":"0.00077327"}]}]}
{"channel":"l2_data","timestamp":"2026-07-30T15:17:56.192034451Z","sequence_num":9,"events":[{"type":"update","product_id":"BTC-USD","updates":[{"side":"bid","event_time":"2026-07-30T15:17:56.119488Z","price_level":"64556.54","new_quantity":"0.04952991"},{"side":"bid","event_time":"2026-07-30T15:17:56.119488Z","price_level":"64421.19","new_quantity":"0.00583"},{"side":"bid","event_time":"2026-07-30T15:17:56.119488Z","price_level":"64420.97","new_quantity":"0.00583"},{"side":"bid","event_time":"2026-07-30T15:17:56.119488Z","price_level":"64420.65","new_quantity":"0"},{"side":"bid","event_time":"2026-07-30T15:17:56.119488Z","price_level":"64419.35","new_quantity":"0"},{"side":"bid","event_time":"2026-07-30T15:17:56.119488Z","price_level":"56570.22","new_quantity":"0.01324455"},{"side":"offer","event_time":"2026-07-30T15:17:56.119488Z","price_level":"64651.68","new_quantity":"0.02801412"},{"side":"offer","event_time":"2026-07-30T15:17:56.119488Z","price_level":"64670.88","new_quantity":"0"}]}]}
{"channel":"l2_data","timestamp":"2026-07-30T15:17:56.210293605Z","sequence_num":10,"events":[{"type":"update","product_id":"BTC-USD","updates":[{"side":"bid","event_time":"2026-07-30T15:17:56.163863Z","price_level":"64603.65","new_quantity":"0.89344555"},{"side":"bid","event_time":"2026-07-30T15:17:56.163863Z","price_level":"64603.64","new_quantity":"2.18378331"},{"side":"bid","event_time":"2026-07-30T15:17:56.163863Z","price_level":"64603.63","new_quantity":"0"},{"side":"bid","event_time":"2026-07-30T15:17:56.163863Z","price_level":"64603.62","new_quantity":"0"},{"side":"offer","event_time":"2026-07-30T15:17:56.163863Z","price_level":"64668.98","new_quantity":"0.65289566"},{"side":"offer","event_time":"2026-07-30T15:17:56.163863Z","price_level":"64668.99","new_quantity":"0.65289566"},{"side":"offer","event_time":"2026-07-30T15:17:56.163863Z","price_level":"64671.99","new_quantity":"0.1803432"},{"side":"offer","event_time":"2026-07-30T15:17:56.163863Z","price_level":"64672.98","new_quantity":"0"},{"side":"offer","event_time":"2026-07-30T15:17:56.163863Z","price_level":"64686.66","new_quantity":"0"}]}]}
{"channel":"l2_data","timestamp":"2026-07-30T15:17:56.260240822Z","sequence_num":11,"events":[{"type":"update","product_id":"BTC-USD","updates":[{"side":"bid","event_time":"2026-07-30T15:17:56.22537Z","price_level":"64626.22","new_quantity":"0.14"},{"side":"bid","event_time":"2026-07-30T15:17:56.22537Z","price_level":"56570.22","new_quantity":"0"},{"side":"offer","event_time":"2026-07-30T15:17:56.22537Z","price_level":"64668.98","new_quantity":"0"},{"side":"offer","event_time":"2026-07-30T15:17:56.22537Z","price_level":"64668.99","new_quantity":"0"},{"side":"offer","event_time":"2026-07-30T15:17:56.22537Z","price_level":"64670.99","new_quantity":"0"},{"side":"offer","event_time":"2026-07-30T15:17:56.22537Z","price_level":"64671.99","new_quantity":"0"},{"side":"offer","event_time":"2026-07-30T15:17:56.22537Z","price_level":"64672.05","new_quantity":"0.14"},{"side":"offer","event_time":"2026-07-30T15:17:56.22537Z","price_level":"64672.99","new_quantity":"0.50679103"},{"side":"offer","event_time":"2026-07-30T15:17:56.22537Z","price_level":"65549.99","new_quantity":"0"},{"side":"offer","event_time":"2026-07-30T15:17:56.22537Z","price_level":"65554.99","new_quantity":"0.31355606"}]}]}
{"channel":"l2_data","timestamp":"2026-07-30T15:17:56.292524839Z","sequence_num":12,"events":[{"type":"snapshot","product_id":"ETH-USD","updates":[{"side":"bid","event_time":"2026-07-30T15:17:55.98381Z","price_level":"1915.44","new_quantity":"0.00198956"},{"side":"bid","event_time":"2026-07-30T15:17:55.98381Z","price_level":"1915.43","new_quantity":"0.00000505"},{"side":"bid","event_time":"2026-07-30T15:17:55.98381Z","price_level":"1915.42","new_quantity":"0.0000053"},{"side":"bid","event_time":"2026-07-30T15:17:55.98381Z","price_level":"1915.4","new_quantity":"0.05"},{"side":"bid","event_time":"2026-07-30T15:17:55.98381Z","price_level":"1915.38","new_quantity":"0.00000508"},{"side":"bid","event_time":"2026-07-30T15:17:55.98381Z","price_level":"1915.37","new_quantity":"0.00001017"},{"side":"bid","event_time":"2026-07-30T15:17:55.98381Z","price_level":"1915.35","new_quantity":"1.04490479"},{"side":"bid","event_time":"2026-07-30T15:17:55.98381Z","price_level":"1915.34","new_quantity":"0.78314967"},{"side":"bid","event_time":"2026-07-30T15:17:55.98381Z","price_level":"1915.32","new_quantity":"0.301"},{"side":"bid","event_time":"2026-07-30T15:17:55.98381Z","price_level":"1915.29","new_quantity":"0.04951335"},{"side":"bid","event_time":"2026-07-30T15:17:55.98381Z","price_level":"1915.28","new_quantity":"1.04490479"},{"side":"bid","event_time":"2026-07-30T15:17:55.98381Z","price_level":"1915.27","new_quantity":"1.04490479"},{"side":"bid","event_time":"2026-07-30T15:17:55.98381Z","price_level":"1915.2","new_quantity":"0.05199478"},{"side":"bid","event_time":"2026-07-30T15:17:55.98381Z","price_level":"1915.19","new_quantity":"1.04490479"},{"side":"bid","event_time":"2026-07-30T15:17:55.98381Z","price_level":"1915.14","new_quantity":"6.28986227"},{"side":"bid","event_time":"2026-07-30T15:17:55.98381Z","price_level":"1915.13","new_quantity":"7.75021302"},{"side":"bid","event_time":"2026-07-30T15:17:55.98381Z","price_level":"1915.12","new_quantity":"1.04490479"},{"side":"bid","event_time":"2026-07-30T15:17:55.98381Z","price_level":"1915.11","new_quantity":"1.04490479"},{"side":"bid","event_time":"2026-07-30T15:17:55.98381Z","price_level":"1915.1","new_quantity":"1.5375"},{"side":"bid","event_time":"2026-07-30T15:17:55.98381Z","price_level":"1915.09","new_quantity":"2.49244124"},{"side":"bid","event_time":"2026-07-30T15:17:55.98381Z","price_level":"1915.08","new_quantity":"2.81986848"},{"side":"bid","event_time":"2026-07-30T15:17:55.98381Z","price_level":"1915.01","new_quantity":"1.04490479"},{"side":"bid","event_time":"2026-07-30T15:17:55.98381Z","price_level":"1915","new_quantity":"45.00681571"},{"side":"bid","event_time":"2026-07-30T15:17:55.98381Z","price_level":"1914.96","new_quantity":"56.43192805"},{"side":"bid","event_time":"2026-07-30T15:17:55.98381Z","price_level":"1914.94","new_quantity":"2.8"},{"side":"bid","event_time":"2026-07-30T15:17:55.98381Z","price_level":"1914.93","new_quantity":"1.04490479"},{"side":"bid","event_time":"2026-07-30T15:17:55.98381Z","price_level":"1914.92","new_quantity":"4.79361267"},{"side":"bid","event_time":"2026-07-30T15:17:55.98381Z","price_level":"1914.91","new_quantity":"1.04490479"},{"side":"bid","event_time":"2026-07-30T15:17:55.98381Z","price_level":"1914.9","new_quantity":"11.54541729"},{"side":"bid","event_time":"2026-07-30T15:17:55.98381Z","price_level":"1914.85","new_quantity":"0.584"},{"side":"bid","event_time":"2026-07-30T15:17:55.98381Z","price_level":"1914.84","new_quantity":"1.98873529"},{"side":"bid","event_time":"2026-07-30T15:17:55.98381Z","price_level":"1914.81","new_quantity":"11.96985"},{"side":"bid","event_time":"2026-07-30T15:17:55.98381Z","price_level":"1914.8","new_quantity":"20.05"},{"side":"bid","event_time":"2026-07-30T15:17:55.98381Z","price_level":"1914.77","new_quantity":"5.44898421"},{"side":"bid","event_time":"2026-07-30T15:17:55.98381Z","price_level":"1914.76","new_quantity":"5.83851746"},{"side":"bid","event_time":"2026-07-30T15:17:55.98381Z","price_level":"1914.72","new_quantity":"0.001"},{"side":"bid","event_time":"2026-07-30T15:17:55.98381Z","price_level":"1914.7","new_quantity":"1.5375"},{"side":"bid","event_time":"2026-07-30T15:17:55.98381Z","price_level":"1914.69","new_quantity":"0.00078317"},{"side":"bid","event_time":"2026-07-30T15:17:55.98381Z","price_level":"1914.68","new_quantity":"3.60216717"},{"side":"bid","event_time":"2026-07-30T15:17:55.98381Z","price_level":"1914.67","new_quantity":"1.04490479"},{"side":"offer","event_time":"2026-07-30T15:17:55.98381Z","price_level":"1915.45","new_quantity":"0.94854243"},{"side":"offer","event_time":"2026-07-30T15:17:55.98381Z","price_level":"1915.46","new_quantity":"1.04950483"},{"side":"offer","event_time":"2026-07-30T15:17:55.98381Z","price_level":"1915.47","new_quantity":"0.4"},{"side":"offer","event_time":"2026-07-30T15:17:55.98381Z","price_level":"1915.48","new_quantity":"1"},{"side":"offer","event_time":"2026-07-30T15:17:55.98381Z","price_level":"1915.58","new_quantity":"0.7830544"},{"side":"offer","event_time":"2026-07-30T15:17:55.98381Z","price_level":"1915.64","new_quantity":"1.44490479"},{"side":"offer","event_time":"2026-07-30T15:17:55.98381Z","price_level":"1915.65","new_quantity":"0.4"},{"side":"offer","event_time":"2026-07-30T15:17:55.98381Z","price_level":"1915.66","new_quantity":"1.5375"},{"side":"offer","event_time":"2026-07-30T15:17:55.98381Z","price_level":"1915.72","new_quantity":"1.10675748"},{"side":"offer","event_time":"2026-07-30T15:17:55.98381Z","price_level":"1915.73","new_quantity":"0.4"},{"side":"offer","event_time":"2026-07-30T15:17:55.98381Z","price_level":"1915.74","new_quantity":"0.00796033"},{"side":"offer","event_time":"2026-07-30T15:17:55.98381Z","price_level":"1915.76","new_quantity":"0.4"},{"side":"offer","event_time":"2026-07-30T15:17:55.98381Z","price_level":"1915.77","new_quantity":"1.04490479"},{"side":"offer","event_time":"2026-07-30T15:17:55.98381Z","price_level":"1915.8","new_quantity":"0.001"},{"side":"offer","event_time":"2026-07-30T15:17:55.98381Z","price_level":"1915.81","new_quantity":"0.4"},{"side":"offer","event_time":"2026-07-30T15:17:55.98381Z","price_level":"1915.82","new_quantity":"4.34820308"},{"side":"offer","event_time":"2026-07-30T15:17:55.98381Z","price_level":"1915.83","new_quantity":"4.79361267"},{"side":"offer","event_time":"2026-07-30T15:17:55.98381Z","price_level":"1915.84","new_quantity":"1.04490479"},{"side":"offer","event_time":"2026-07-30T15:17:55.98381Z","price_level":"1915.85","new_quantity":"1.04490479"},{"side":"offer","event_time":"2026-07-30T15:17:55.98381Z","price_level":"1915.92","new_quantity":"0.001"},{"side":"offer","event_time":"2026-07-30T15:17:55.98381Z","price_level":"1915.93","new_quantity":"41.98135953"},{"side":"offer","event_time":"2026-07-30T15:17:55.98381Z","price_level":"1915.94","new_quantity":"1.5375"},{"side":"offer","event_time":"2026-07-30T15:17:55.98381Z","price_level":"1915.97","new_quantity":"2.81886848"},{"side":"offer","event_time":"2026-07-30T15:17:55.98381Z","price_level":"1915.98","new_quantity":"59.8083449"},{"side":"offer","event_time":"2026-07-30T15:17:55.98381Z","price_level":"1915.99","new_quantity":"1.74490479"},{"side":"offer","event_time":"2026-07-30T15:17:55.98381Z","price_level":"1916","new_quantity":"20.62440516"},{"side":"offer","event_time":"2026-07-30T15:17:55.98381Z","price_level":"1916.01","new_quantity":"1.04490479"},{"side":"offer","event_time":"2026-07-30T15:17:55.98381Z","price_level":"1916.04","new_quantity":"0.001"},{"side":"offer","event_time":"2026-07-30T15:17:55.98381Z","price_level":"1916.11","new_quantity":"1.04490479"},{"side":"offer","event_time":"2026-07-30T15:17:55.98381Z","price_level":"1916.16","new_quantity":"2.88340479"},{"side":"offer","event_time":"2026-07-30T15:17:55.98381Z","price_level":"1916.17","new_quantity":"14.21671575"},{"side":"offer","event_time":"2026-07-30T15:17:55.98381Z","price_level":"1916.18","new_quantity":"4.79361267"},{"side":"offer","event_time":"2026-07-30T15:17:55.98381Z","price_level":"1916.19","new_quantity":"1.04490479"},{"side":"offer","event_time":"2026-07-30T15:17:55.98381Z","price_level":"1916.2","new_quantity":"20"},{"side":"offer","event_time":"2026-07-30T15:17:55.98381Z","price_level":"1916.21","new_quantity":"0.00078303"},{"side":"offer","event_time":"2026-07-30T15:17:55.98381Z","price_level":"1916.26","new_quantity":"7.98544551"},{"side":"offer","event_time":"2026-07-30T15:17:55.98381Z","price_level":"1916.27","new_quantity":"1.87561513"},{"side":"offer","event_time":"2026-07-30T15:17:55.98381Z","price_level":"1916.28","new_quantity":"1.04590479"},{"side":"offer","event_time":"2026-07-30T15:17:55.98381Z","price_level":"1916.3","new_quantity":"14.49911004"},{"side":"offer","event_time":"2026-07-30T15:17:55.98381Z","price_level":"1916.34","new_quantity":"4.79361267"}]}]}
{"channel":"l2_data","timestamp":"2026-07-30T15:17:56.313756774Z","sequence_num":13,"events":[{"type":"update","product_id":"BTC-USD","updates":[{"side":"bid","event_time":"2026-07-30T15:17:56.277772Z","price_level":"64648.04","new_quantity":"0"},{"side":"bid","event_time":"2026-07-30T15:17:56.277772Z","price_level":"64648.02","new_quantity":"0.04"},{"side":"bid","event_time":"2026-07-30T15:17:56.277772Z","price_level":"64625.16","new_quantity":"0"},{"side":"bid","event_time":"2026-07-30T15:17:56.277772Z","price_level":"64618.71","new_quantity":"0"},{"side":"bid","event_time":"2026-07-30T15:17:56.277772Z","price_level":"64603.67","new_quantity":"0.89344527"},{"side":"bid","event_time":"2026-07-30T15:17:56.277772Z","price_level":"64603.66","new_quantity":"2.18378263"},{"side":"bid","event_time":"2026-07-30T15:17:56.277772Z","price_level":"64603.65","new_quantity":"0"},{"side":"bid","event_time":"2026-07-30T15:17:56.277772Z","price_level":"64603.64","new_quantity":"0"},{"side":"bid","event_time":"2026-07-30T15:17:56.277772Z","price_level":"64420.97","new_quantity":"0"},{"side":"bid","event_time":"2026-07-30T15:17:56.277772Z","price_level":"64205.76","new_quantity":"0.00583"},{"side":"offer","event_time":"2026-07-30T15:17:56.277772Z","price_level":"64664.15","new_quantity":"0.00613016"},{"side":"offer","event_time":"2026-07-30T15:17:56.277772Z","price_level":"64688.19","new_quantity":"0.15458542"},{"side":"offer","event_time":"2026-07-30T15:17:56.277772Z","price_level":"65747.5","new_quantity":"0.00583"},{"side":"offer","event_time":"2026-07-30T15:17:56.277772Z","price_level":"65747.85","new_quantity":"0"}]}]}
{"channel":"l2_data","timestamp":"2026-07-30T15:17:56.315061918Z","sequence_num":14,"events":[{"type":"update","product_id":"ETH-USD","updates":[{"side":"bid","event_time":"2026-07-30T15:17:56.046336Z","price_level":"1676.01","new_quantity":"0.02977812"},{"side":"offer","event_time":"2026-07-30T15:17:56.046336Z","price_level":"1916.43","new_quantity":"2.84263655"},{"side":"offer","event_time":"2026-07-30T15:17:56.046336Z","price_level":"1916.51","new_quantity":"6.62425516"},{"side":"offer","event_time":"2026-07-30T15:17:56.046336Z","price_level":"1916.54","new_quantity":"0"}]}]}
{"channel":"subscriptions","timestamp":"2026-07-30T15:17:56.315741905Z","sequence_num":15,"events":[{"subscriptions":{"level2":["BTC-USD","ETH-USD"]}}]}
{"channel":"market_trades","timestamp":"2026-07-30T15:17:56.315984077Z","sequence_num":16,"events":[{"type":"snapshot","trades":[{"product_id":"BTC-USD","trade_id":"1064604826","price":"64651.68","size":"0.00153112","time":"2026-07-30T15:17:56.104519Z","side":"SELL"},{"product_id":"BTC-USD","trade_id":"1064604825","price":"64651.68","size":"0.00007273","time":"2026-07-30T15:17:56.085177Z","side":"SELL"},{"product_id":"BTC-USD","trade_id":"1064604824","price":"64651.68","size":"0.00030622","time":"2026-07-30T15:17:55.572523Z","side":"SELL"},{"product_id":"BTC-USD","trade_id":"1064604823","price":"64651.68","size":"0.00007273","time":"2026-07-30T15:17:55.397319Z","side":"SELL"},{"product_id":"BTC-USD","trade_id":"1064604822","price":"64651.68","size":"0.00014929","time":"2026-07-30T15:17:55.247864Z","side":"SELL"},{"product_id":"BTC-USD","trade_id":"1064604821","price":"64651.68","size":"0.00075148","time":"2026-07-30T15:17:54.996046Z","side":"SELL"},{"product_id":"BTC-USD","trade_id":"1064604820","price":"64651.91","size":"0.00052609","time":"2026-07-30T15:17:54.774304Z","side":"SELL"},{"product_id":"BTC-USD","trade_id":"1064604819","price":"64651.91","size":"0.00000386","time":"2026-07-30T15:17:54.704983Z","side":"SELL"},{"product_id":"BTC-USD","trade_id":"1064604818","price":"64651.92","size":"0.00001531","time":"2026-07-30T15:17:54.194248Z","side":"SELL"},{"product_id":"BTC-USD","trade_id":"1064604817","price":"64656.65","size":"0.00009439","time":"2026-07-30T15:17:53.982059Z","side":"BUY"},{"product_id":"BTC-USD","trade_id":"1064604816","price":"64656.65","size":"0.0132","time":"2026-07-30T15:17:53.952194Z","side":"BUY"},{"product_id":"BTC-USD","trade_id":"1064604815","price":"64657.54","size":"0.00001888","time":"2026-07-30T15:17:53.949841Z","side":"BUY"},{"product_id":"BTC-USD","trade_id":"1064604814","price":"64657.95","size":"0.02370537","time":"2026-07-30T15:17:53.948717Z","side":"BUY"},{"product_id":"BTC-USD","trade_id":"1064604813","price":"64657.95","size":"0.44830952","time":"2026-07-30T15:17:53.948717Z","side":"BUY"},{"product_id":"BTC-USD","trade_id":"1064604812","price":"64657.96","size":"0.00137863","time":"2026-07-30T15:17:53.768742Z","side":"SELL"},{"product_id":"BTC-USD","trade_id":"1064604811","price":"64657.96","size":"0.00008699","time":"2026-07-30T15:17:53.768742Z","side":"SELL"},{"product_id":"BTC-USD","trade_id":"1064604810","price":"64657.95","size":"0.00000029","time":"2026-07-30T15:17:53.626072Z","side":"BUY"},{"product_id":"BTC-USD","trade_id":"1064604809","price":"64657.95","size":"0.00000006","time":"2026-07-30T15:17:53.476356Z","side":"BUY"},{"product_id":"BTC-USD","trade_id":"1064604808","price":"64657.95","size":"0.00008218","time":"2026-07-30T15:17:53.431324Z","side":"BUY"},{"product_id":"BTC-USD","trade_id":"1064604807","price":"64657.96","size":"0.00004502","time":"2026-07-30T15:17:53.376774Z","side":"SELL"},{"product_id":"BTC-USD","trade_id":"1064604806","price":"64657.96","size":"0.00013104","time":"2026-07-30T15:17:53.358011Z","side":"SELL"},{"product_id":"BTC-USD","trade_id":"1064604805","price":"64657.96","size":"0.00001932","time":"2026-07-30T15:17:53.358011Z","side":"SELL"},{"product_id":"BTC-USD","trade_id":"1064604804","price":"64657.95","size":"0.00000006","time":"2026-07-30T15:17:52.391446Z","side":"BUY"},{"product_id":"BTC-USD","trade_id":"1064604803","price":"64657.96","size":"0.00001501","time":"2026-07-30T15:17:51.95463Z","side":"SELL"},{"product_id":"BTC-USD","trade_id":"1064604802","price":"64657.95","size":"0.00000014","time":"2026-07-30T15:17:51.098501Z","side":"BUY"},{"product_id":"BTC-USD","trade_id":"1064604801","price":"64657.95","size":"0.01558767","time":"2026-07-30T15:17:51.039155Z","side":"BUY"},{"product_id":"BTC-USD","trade_id":"1064604800","price":"64657.95","size":"0.00000006","time":"2026-07-30T15:17:50.810833Z","side":"BUY"},{"product_id":"BTC-USD","trade_id":"1064604799","price":"64657.95","size":"0.00000005","time":"2026-07-30T15:17:50.568295Z","side":"BUY"},{"product_id":"BTC-USD","trade_id":"1064604798","price":"64657.96","size":"0.00340001","time":"2026-07-30T15:17:50.476429Z","side":"SELL"},{"product_id":"BTC-USD","trade_id":"1064604797","price":"64659.12","size":"0.0005275","time":"2026-07-30T15:17:50.106074Z","side":"SELL"},{"product_id":"BTC-USD","trade_id":"1064604796","price":"64657.55","size":"0.00026849","time":"2026-07-30T15:17:50.106074Z","side":"SELL"},{"product_id":"BTC-USD","trade_id":"1064604795","price":"64657.55","size":"0.00015785","time":"2026-07-30T15:17:50.106074Z","side":"SELL"},{"product_id":"BTC-USD","trade_id":"1064604794","price":"64657.54","size":"0.00000026","time":"2026-07-30T15:17:49.987422Z","side":"BUY"},{"product_id":"BTC-USD","trade_id":"1064604793","price":"64657.54","size":"0.00000003","time":"2026-07-30T15:17:49.822437Z","side":"BUY"},{"product_id":"BTC-USD","trade_id":"1064604792","price":"64657.54","size":"0.0043313","time":"2026-07-30T15:17:49.759634Z","side":"SELL"},{"product_id":"BTC-USD","trade_id":"1064604791","price":"64657.54","size":"0.00031318","time":"2026-07-30T15:17:49.759634Z","side":"SELL"},{"product_id":"BTC-USD","trade_id":"1064604790","price":"64657.54","size":"0.00008528","time":"2026-07-30T15:17:49.759634Z","side":"SELL"},{"product_id":"BTC-USD","trade_id":"1064604789","price":"64657.54","size":"0.000018","time":"2026-07-30T15:17:49.759634Z","side":"SELL"},{"product_id":"BTC-USD","trade_id":"1064604788","price":"64657.53","size":"0.00000025","time":"2026-07-30T15:17:49.50882Z","side":"BUY"},{"product_id":"BTC-USD","trade_id":"1064604787","price":"64657.53","size":"0.00000015","time":"2026-07-30T15:17:49.240616Z","side":"BUY"},{"product_id":"BTC-USD","trade_id":"1064604786","price":"64657.53","size":"0.00002165","time":"2026-07-30T15:17:49.231331Z","side":"BUY"},{"product_id":"BTC-USD","trade_id":"1064604785","price":"64654.24","size":"0.00017895","time":"2026-07-30T15:17:49.060101Z","side":"SELL"},{"product_id":"BTC-USD","trade_id":"1064604784","price":"64654.23","size":"0.00008955","time":"2026-07-30T15:17:49.060101Z","side":"SELL"},{"product_id":"BTC-USD","trade_id":"1064604783","price":"64654.23","size":"0.00028936","time":"2026-07-30T15:17:49.060101Z","side":"SELL"},{"product_id":"BTC-USD","trade_id":"1064604782","price":"64654.23","size":"0.000018","time":"2026-07-30T15:17:49.060101Z","side":"SELL"},{"product_id":"BTC-USD","trade_id":"1064604781","price":"64654.22","size":"0.00000006","time":"2026-07-30T15:17:48.91105Z","side":"BUY"},{"product_id":"BTC-USD","trade_id":"1064604780","price":"64654.22","size":"0.0000001","time":"2026-07-30T15:17:48.838077Z","side":"BUY"},{"product_id":"BTC-USD","trade_id":"1064604779","price":"64650.93","size":"0.00006264","time":"2026-07-30T15:17:48.562717Z","side":"SELL"},{"product_id":"BTC-USD","trade_id":"1064604778","price":"64650.92","size":"0.04341788","time":"2026-07-30T15:17:48.562717Z","side":"SELL"},{"product_id":"BTC-USD","trade_id":"1064604777","price":"64650.92","size":"0.07389059","time":"2026-07-30T15:17:48.562644Z","side":"SELL"},{"product_id":"BTC-USD","trade_id":"1064604776","price":"64650.92","size":"0.15101395","time":"2026-07-30T15:17:48.558556Z","side":"SELL"},{"product_id":"BTC-USD","trade_id":"1064604775","price":"64650.92","size":"0.09253153","time":"2026-07-30T15:17:48.557075Z","side":"SELL"},{"product_id":"BTC-USD","trade_id":"1064604774","price":"64650.92","size":"0.13914605","time":"2026-07-30T15:17:48.55542Z","side":"SELL"},{"product_id":"BTC-USD","trade_id":"1064604773","price":"64650.92","size":"0.033","time":"2026-07-30T15:17:48.55542Z","side":"SELL"},{"product_id":"BTC-USD","trade_id":"1064604772","price":"64650.92","size":"0.000018","time":"2026-07-30T15:17:48.55542Z","side":"SELL"},{"product_id":"BTC-USD","trade_id":"1064604771","price":"64648.52","size":"0.116079","time":"2026-07-30T15:17:47.871994Z","side":"SELL"},{"product_id":"BTC-USD","trade_id":"1064604770","price":"64648.52","size":"0.00116025","time":"2026-07-30T15:17:47.871994Z","side":"SELL"},{"product_id":"BTC-USD","trade_id":"1064604769","price":"64644.31","size":"0.25","time":"2026-07-30T15:17:47.84296Z","side":"SELL"},{"product_id":"BTC-USD","trade_id":"1064604768","price":"64644.31","size":"0.00023149","time":"2026-07-30T15:17:47.84296Z","side":"SELL"},{"product_id":"BTC-USD","trade_id":"1064604767","price":"64642.76","size":"0.1237571","time":"2026-07-30T15:17:47.476765Z","side":"SELL"},{"product_id":"BTC-USD","trade_id":"1064604766","price":"64642.62","size":"0.00773502","time":"2026-07-30T15:17:47.476765Z","side":"SELL"},{"product_id":"BTC-USD","trade_id":"1064604765","price":"64642.5","size":"0.00150724","time":"2026-07-30T15:17:47.476765Z","side":"SELL"},{"product_id":"BTC-USD","trade_id":"1064604764","price":"64642.3","size":"0.01546975","time":"2026-07-30T15:17:47.476765Z","side":"SELL"},{"product_id":"BTC-USD","trade_id":"1064604763","price":"64642.3","size":"0.01546975","time":"2026-07-30T15:17:47.476765Z","side":"SELL"},{"product_id":"BTC-USD","trade_id":"1064604762","price":"64641","size":"0.00005787","time":"2026-07-30T15:17:47.476686Z","side":"SELL"},{"product_id":"BTC-USD","trade_id":"1064604761","price":"64641","size":"0.00008957","time":"2026-07-30T15:17:47.476686Z","side":"SELL"},{"product_id":"BTC-USD","trade_id":"1064604760","price":"64641","size":"0.00773502","time":"2026-07-30T15:17:47.476686Z","side":"SELL"},{"product_id":"BTC-USD","trade_id":"1064604759","price":"64641","size":"0.02849706","time":"2026-07-30T15:17:47.476686Z","side":"SELL"},{"product_id":"BTC-USD","trade_id":"1064604758","price":"64641","size":"0.0132","time":"2026-07-30T15:17:47.476607Z","side":"SELL"},{"product_id":"BTC-USD","trade_id":"1064604757","price":"64641","size":"0.00891601","time":"2026-07-30T15:17:47.441047Z","side":"SELL"},{"product_id":"BTC-USD","trade_id":"1064604756","price":"64641","size":"0.00220059","time":"2026-07-30T15:17:41.192491Z","side":"SELL"},{"product_id":"BTC-USD","trade_id":"1064604755","price":"64641","size":"0.00000015","time":"2026-07-30T15:17:36.649563Z","side":"SELL"},{"product_id":"BTC-USD","trade_id":"1064604754","price":"64642.31","size":"0.00773487","time":"2026-07-30T15:17:36.639726Z","side":"BUY"},{"product_id":"BTC-USD","trade_id":"1064604753","price":"64642.31","size":"0.00773487","time":"2026-07-30T15:17:36.639726Z","side":"BUY"},{"product_id":"BTC-USD","trade_id":"1064604752","price":"64644.3","size":"0.000018","time":"2026-07-30T15:17:36.639726Z","side":"BUY"},{"product_id":"BTC-USD","trade_id":"1064604751","price":"64644.31","size":"0.00002706","time":"2026-07-30T15:17:36.634814Z","side":"SELL"},{"product_id":"BTC-USD","trade_id":"1064604750","price":"64645","size":"0.01","time":"2026-07-30T15:17:36.560091Z","side":"BUY"},{"product_id":"BTC-USD","trade_id":"1064604749","price":"64647.16","size":"0.00000004","time":"2026-07-30T15:17:36.560091Z","side":"BUY"},{"product_id":"BTC-USD","trade_id":"1064604748","price":"64647.16","size":"0.00000002","time":"2026-07-30T15:17:36.035332Z","side":"BUY"},{"product_id":"BTC-USD","trade_id":"1064604747","price":"64647.16","size":"0.00000009","time":"2026-07-30T15:17:35.960563Z","side":"BUY"},{"product_id":"BTC-USD","trade_id":"1064604746","price":"64647.16","size":"0.06045507","time":"2026-07-30T15:17:35.86524Z","side":"BUY"},{"product_id":"BTC-USD","trade_id":"1064604745","price":"64647.16","size":"0.01938707","time":"2026-07-30T15:17:35.864066Z","side":"BUY"},{"product_id":"BTC-USD","trade_id":"1064604744","price":"64647.16","size":"0.00773429","time":"2026-07-30T15:17:35.864066Z","side":"BUY"},{"product_id":"BTC-USD","trade_id":"1064604743","price":"64647.16","size":"0.00773429","time":"2026-07-30T15:17:35.864066Z","side":"BUY"},{"product_id":"BTC-USD","trade_id":"1064604742","price":"64647.61","size":"0.000018","time":"2026-07-30T15:17:35.816105Z","side":"BUY"},{"product_id":"BTC-USD","trade_id":"1064604741","price":"64649.97","size":"0.00000018","time":"2026-07-30T15:17:35.816105Z","side":"BUY"},{"product_id":"BTC-USD","trade_id":"1064604740","price":"64650.92","size":"0.000018","time":"2026-07-30T15:17:35.816105Z","side":"BUY"},{"product_id":"BTC-USD","trade_id":"1064604739","price":"64651.02","size":"0.18478583","time":"2026-07-30T15:17:35.705222Z","side":"BUY"},{"product_id":"BTC-USD","trade_id":"1064604738","price":"64652.01","size":"0.00757532","time":"2026-07-30T15:17:35.705222Z","side":"BUY"},{"product_id":"BTC-USD","trade_id":"1064604737","price":"64652.01","size":"0.00000335","time":"2026-07-30T15:17:35.569578Z","side":"BUY"},{"product_id":"BTC-USD","trade_id":"1064604736","price":"64652.01","size":"0.00000006","time":"2026-07-30T15:17:35.568183Z","side":"BUY"},{"product_id":"BTC-USD","trade_id":"1064604735","price":"64652.02","size":"0.00765611","time":"2026-07-30T15:17:35.121586Z","side":"SELL"},{"product_id":"BTC-USD","trade_id":"1064604734","price":"64654.23","size":"0.00105669","time":"2026-07-30T15:17:34.864655Z","side":"BUY"},{"product_id":"BTC-USD","trade_id":"1064604733","price":"64654.23","size":"0.00021158","time":"2026-07-30T15:17:34.864655Z","side":"BUY"},{"product_id":"BTC-USD","trade_id":"1064604732","price":"64654.23","size":"0.00003949","time":"2026-07-30T15:17:34.864655Z","side":"BUY"},{"product_id":"BTC-USD","trade_id":"1064604731","price":"64654.23","size":"0.02602045","time":"2026-07-30T15:17:34.864655Z","side":"BUY"},{"product_id":"BTC-USD","trade_id":"1064604730","price":"64654.23","size":"0.01894302","time":"2026-07-30T15:17:34.864655Z","side":"BUY"},{"product_id":"BTC-USD","trade_id":"1064604729","price":"64654.23","size":"0.02103088","time":"2026-07-30T15:17:34.864655Z","side":"BUY"},{"product_id":"BTC-USD","trade_id":"1064604728","price":"64654.23","size":"0.00001791","time":"2026-07-30T15:17:34.864655Z","side":"BUY"},{"product_id":"BTC-USD","trade_id":"1064604727","price":"64654.23","size":"0.00000009","time":"2026-07-30T15:17:34.521532Z","side":"BUY"}]}]}
{"channel":"market_trades","timestamp":"2026-07-30T15:17:56.316189802Z","sequence_num":17,"events":[{"type":"snapshot","trades":[{"product_id":"ETH-USD","trade_id":"831263588","price":"1915.45","size":"0.02584236","time":"2026-07-30T15:17:56.212131Z","side":"SELL"},{"product_id":"ETH-USD","trade_id":"831263587","price":"1915.45","size":"0.00503852","time":"2026-07-30T15:17:54.454353Z","side":"SELL"},{"product_id":"ETH-USD","trade_id":"831263586","price":"1915.45","size":"0.01291929","time":"2026-07-30T15:17:54.22728Z","side":"SELL"},{"product_id":"ETH-USD","trade_id":"831263585","price":"1915.46","size":"0.00503852","time":"2026-07-30T15:17:53.663938Z","side":"SELL"},{"product_id":"ETH-USD","trade_id":"831263584","price":"1915.65","size":"0.04951335","time":"2026-07-30T15:17:51.736497Z","side":"BUY"},{"product_id":"ETH-USD","trade_id":"831263583","price":"1915.67","size":"0.78301487","time":"2026-07-30T15:17:51.735789Z","side":"BUY"},{"product_id":"ETH-USD","trade_id":"831263582","price":"1915.69","size":"0.00000628","time":"2026-07-30T15:17:51.735789Z","side":"BUY"},{"product_id":"ETH-USD","trade_id":"831263581","price":"1915.7","size":"0.00000598","time":"2026-07-30T15:17:51.735789Z","side":"BUY"},{"product_id":"ETH-USD","trade_id":"831263580","price":"1915.71","size":"0.00000568","time":"2026-07-30T15:17:51.735789Z","side":"BUY"},{"product_id":"ETH-USD","trade_id":"831263579","price":"1915.73","size":"0.52192478","time":"2026-07-30T15:17:51.735789Z","side":"BUY"},{"product_id":"ETH-USD","trade_id":"831263578","price":"1915.73","size":"0.00000541","time":"2026-07-30T15:17:51.735789Z","side":"BUY"},{"product_id":"ETH-USD","trade_id":"831263577","price":"1915.94","size":"0.16138982","time":"2026-07-30T15:17:50.579952Z","side":"SELL"},{"product_id":"ETH-USD","trade_id":"831263576","price":"1915.93","size":"1.04490479","time":"2026-07-30T15:17:50.579952Z","side":"SELL"},{"product_id":"ETH-USD","trade_id":"831263575","price":"1915.92","size":"0.001","time":"2026-07-30T15:17:50.579952Z","side":"SELL"},{"product_id":"ETH-USD","trade_id":"831263574","price":"1915.9","size":"0.00265355","time":"2026-07-30T15:17:50.579952Z","side":"SELL"},{"product_id":"ETH-USD","trade_id":"831263573","price":"1915.88","size":"0.7829321","time":"2026-07-30T15:17:50.579952Z","side":"SELL"},{"product_id":"ETH-USD","trade_id":"831263572","price":"1915.87","size":"0.04951335","time":"2026-07-30T15:17:50.579952Z","side":"SELL"},{"product_id":"ETH-USD","trade_id":"831263571","price":"1915.8","size":"0.001","time":"2026-07-30T15:17:50.579952Z","side":"SELL"},{"product_id":"ETH-USD","trade_id":"831263570","price":"1915.76","size":"1","time":"2026-07-30T15:17:50.579952Z","side":"SELL"},{"product_id":"ETH-USD","trade_id":"831263569","price":"1915.74","size":"0.00031328","time":"2026-07-30T15:17:50.579952Z","side":"SELL"},{"product_id":"ETH-USD","trade_id":"831263568","price":"1915.74","size":"0.95629311","time":"2026-07-30T15:17:50.579952Z","side":"SELL"},{"product_id":"ETH-USD","trade_id":"831263567","price":"1915.74","size":"1","time":"2026-07-30T15:17:50.579952Z","side":"SELL"},{"product_id":"ETH-USD","trade_id":"831263566","price":"1915.73","size":"0.31477731","time":"2026-07-30T15:17:49.296059Z","side":"BUY"},{"product_id":"ETH-USD","trade_id":"831263565","price":"1915.61","size":"0.54253684","time":"2026-07-30T15:17:48.431829Z","side":"BUY"},{"product_id":"ETH-USD","trade_id":"831263564","price":"1915.63","size":"1.04490479","time":"2026-07-30T15:17:48.431829Z","side":"BUY"},{"product_id":"ETH-USD","trade_id":"831263563","price":"1915.73","size":"0.5219668","time":"2026-07-30T15:17:48.431829Z","side":"BUY"},{"product_id":"ETH-USD","trade_id":"831263562","price":"1915.46","size":"0.573","time":"2026-07-30T15:17:48.033336Z","side":"SELL"},{"product_id":"ETH-USD","trade_id":"831263561","price":"1915.46","size":"0.427","time":"2026-07-30T15:17:48.033072Z","side":"SELL"},{"product_id":"ETH-USD","trade_id":"831263560","price":"1915.45","size":"1.06966768","time":"2026-07-30T15:17:47.873572Z","side":"SELL"},{"product_id":"ETH-USD","trade_id":"831263559","price":"1915.45","size":"0.00007831","time":"2026-07-30T15:17:47.873572Z","side":"SELL"},{"product_id":"ETH-USD","trade_id":"831263558","price":"1915.64","size":"1.23644094","time":"2026-07-30T15:17:45.112616Z","side":"SELL"},{"product_id":"ETH-USD","trade_id":"831263557","price":"1915.64","size":"1.04490479","time":"2026-07-30T15:17:45.112616Z","side":"SELL"},{"product_id":"ETH-USD","trade_id":"831263556","price":"1915.46","size":"0.00028935","time":"2026-07-30T15:17:45.112616Z","side":"SELL"},{"product_id":"ETH-USD","trade_id":"831263555","price":"1915.56","size":"0.58701956","time":"2026-07-30T15:17:45.051177Z","side":"SELL"},{"product_id":"ETH-USD","trade_id":"831263554","price":"1915.48","size":"0.26144864","time":"2026-07-30T15:17:45.051177Z","side":"SELL"},{"product_id":"ETH-USD","trade_id":"831263553","price":"1915.48","size":"0.00106225","time":"2026-07-30T15:17:45.050498Z","side":"SELL"},{"product_id":"ETH-USD","trade_id":"831263552","price":"1915.48","size":"0.73748911","time":"2026-07-30T15:17:45.047834Z","side":"SELL"},{"product_id":"ETH-USD","trade_id":"831263551","price":"1915.46","size":"0.00000652","time":"2026-07-30T15:17:45.047834Z","side":"SELL"},{"product_id":"ETH-USD","trade_id":"831263550","price":"1915.46","size":"0.80000437","time":"2026-07-30T15:17:45.047834Z","side":"SELL"},{"product_id":"ETH-USD","trade_id":"831263549","price":"1915.46","size":"0.19999563","time":"2026-07-30T15:17:45.045693Z","side":"SELL"},{"product_id":"ETH-USD","trade_id":"831263548","price":"1915.45","size":"0.80001089","time":"2026-07-30T15:17:45.041418Z","side":"SELL"},{"product_id":"ETH-USD","trade_id":"831263547","price":"1915.45","size":"0.04951335","time":"2026-07-30T15:17:45.041418Z","side":"SELL"},{"product_id":"ETH-USD","trade_id":"831263546","price":"1915.45","size":"0.00000621","time":"2026-07-30T15:17:45.041418Z","side":"SELL"},{"product_id":"ETH-USD","trade_id":"831263545","price":"1915.45","size":"0.00000616","time":"2026-07-30T15:17:45.041418Z","side":"SELL"},{"product_id":"ETH-USD","trade_id":"831263544","price":"1915.45","size":"0.00072872","time":"2026-07-30T15:17:45.041418Z","side":"SELL"},{"product_id":"ETH-USD","trade_id":"831263543","price":"1915.45","size":"1.08107788","time":"2026-07-30T15:17:45.041418Z","side":"SELL"},{"product_id":"ETH-USD","trade_id":"831263542","price":"1915.45","size":"0.00143536","time":"2026-07-30T15:17:44.82744Z","side":"SELL"},{"product_id":"ETH-USD","trade_id":"831263541","price":"1915.45","size":"0.04807239","time":"2026-07-30T15:17:44.82744Z","side":"SELL"},{"product_id":"ETH-USD","trade_id":"831263540","price":"1915.44","size":"0.00000522","time":"2026-07-30T15:17:43.613934Z","side":"BUY"},{"product_id":"ETH-USD","trade_id":"831263539","price":"1915.44","size":"0.00000522","time":"2026-07-30T15:17:43.36767Z","side":"BUY"},{"product_id":"ETH-USD","trade_id":"831263538","price":"1915.45","size":"0.00051685","time":"2026-07-30T15:17:42.682072Z","side":"SELL"},{"product_id":"ETH-USD","trade_id":"831263537","price":"1915.45","size":"0.00092411","time":"2026-07-30T15:17:39.046218Z","side":"SELL"},{"product_id":"ETH-USD","trade_id":"831263536","price":"1915.45","size":"0.00028935","time":"2026-07-30T15:17:39.046218Z","side":"SELL"},{"product_id":"ETH-USD","trade_id":"831263535","price":"1915.49","size":"0.00004751","time":"2026-07-30T15:17:36.448661Z","side":"BUY"},{"product_id":"ETH-USD","trade_id":"831263534","price":"1915.49","size":"0.78304167","time":"2026-07-30T15:17:36.44812Z","side":"BUY"},{"product_id":"ETH-USD","trade_id":"831263533","price":"1915.5","size":"0.00595833","time":"2026-07-30T15:17:36.44812Z","side":"BUY"},{"product_id":"ETH-USD","trade_id":"831263532","price":"1915.56","size":"0.001","time":"2026-07-30T15:17:36.444396Z","side":"BUY"},{"product_id":"ETH-USD","trade_id":"831263531","price":"1915.57","size":"0.2","time":"2026-07-30T15:17:36.444396Z","side":"BUY"},{"product_id":"ETH-USD","trade_id":"831263530","price":"1915.57","size":"0.1","time":"2026-07-30T15:17:36.444396Z","side":"BUY"},{"product_id":"ETH-USD","trade_id":"831263529","price":"1915.58","size":"0.00173298","time":"2026-07-30T15:17:36.444396Z","side":"BUY"},{"product_id":"ETH-USD","trade_id":"831263528","price":"1915.6","size":"0.05","time":"2026-07-30T15:17:36.444396Z","side":"BUY"},{"product_id":"ETH-USD","trade_id":"831263527","price":"1915.68","size":"0.001","time":"2026-07-30T15:17:36.444396Z","side":"BUY"},{"product_id":"ETH-USD","trade_id":"831263526","price":"1915.69","size":"0.10144307","time":"2026-07-30T15:17:36.427752Z","side":"SELL"},{"product_id":"ETH-USD","trade_id":"831263525","price":"1915.76","size":"0.1553216","time":"2026-07-30T15:17:35.787898Z","side":"BUY"},{"product_id":"ETH-USD","trade_id":"831263524","price":"1915.79","size":"0.1","time":"2026-07-30T15:17:35.787898Z","side":"BUY"},{"product_id":"ETH-USD","trade_id":"831263523","price":"1915.79","size":"0.2","time":"2026-07-30T15:17:35.787898Z","side":"BUY"},{"product_id":"ETH-USD","trade_id":"831263522","price":"1915.8","size":"0.04999563","time":"2026-07-30T15:17:35.784059Z","side":"BUY"},{"product_id":"ETH-USD","trade_id":"831263521","price":"1915.8","size":"0.001","time":"2026-07-30T15:17:35.784059Z","side":"BUY"},{"product_id":"ETH-USD","trade_id":"831263520","price":"1915.84","size":"0.00000437","time":"2026-07-30T15:17:35.784059Z","side":"BUY"},{"product_id":"ETH-USD","trade_id":"831263519","price":"1915.86","size":"0.04951335","time":"2026-07-30T15:17:35.783865Z","side":"BUY"},{"product_id":"ETH-USD","trade_id":"831263518","price":"1915.88","size":"0.00000457","time":"2026-07-30T15:17:35.783865Z","side":"BUY"},{"product_id":"ETH-USD","trade_id":"831263517","price":"1915.89","size":"0.00000435","time":"2026-07-30T15:17:35.783865Z","side":"BUY"},{"product_id":"ETH-USD","trade_id":"831263516","price":"1915.89","size":"0.00000481","time":"2026-07-30T15:17:35.783865Z","side":"BUY"},{"product_id":"ETH-USD","trade_id":"831263515","price":"1915.91","size":"0.0017598","time":"2026-07-30T15:17:33.841316Z","side":"SELL"},{"product_id":"ETH-USD","trade_id":"831263514","price":"1915.92","size":"0.00074396","time":"2026-07-30T15:17:33.4836Z","side":"SELL"},{"product_id":"ETH-USD","trade_id":"831263513","price":"1915.92","size":"0.001","time":"2026-07-30T15:17:32.066453Z","side":"BUY"},{"product_id":"ETH-USD","trade_id":"831263512","price":"1915.93","size":"0.03575133","time":"2026-07-30T15:17:31.05409Z","side":"SELL"},{"product_id":"ETH-USD","trade_id":"831263511","price":"1915.93","size":"0.02990374","time":"2026-07-30T15:17:29.868019Z","side":"SELL"},{"product_id":"ETH-USD","trade_id":"831263510","price":"1915.93","size":"0.00265352","time":"2026-07-30T15:17:29.868019Z","side":"SELL"},{"product_id":"ETH-USD","trade_id":"831263509","price":"1915.98","size":"0.15532","time":"2026-07-30T15:17:27.049029Z","side":"BUY"},{"product_id":"ETH-USD","trade_id":"831263508","price":"1916","size":"0.00149","time":"2026-07-30T15:17:27.04484Z","side":"BUY"},{"product_id":"ETH-USD","trade_id":"831263507","price":"1916","size":"0.04851","time":"2026-07-30T15:17:27.044512Z","side":"BUY"},{"product_id":"ETH-USD","trade_id":"831263506","price":"1916.04","size":"0.001","time":"2026-07-30T15:17:27.044512Z","side":"BUY"},{"product_id":"ETH-USD","trade_id":"831263505","price":"1916.14","size":"0.0000323","time":"2026-07-30T15:17:27.041171Z","side":"BUY"},{"product_id":"ETH-USD","trade_id":"831263504","price":"1916.14","size":"0.0999677","time":"2026-07-30T15:17:27.040978Z","side":"BUY"},{"product_id":"ETH-USD","trade_id":"831263503","price":"1916.14","size":"0.2","time":"2026-07-30T15:17:27.040978Z","side":"BUY"},{"product_id":"ETH-USD","trade_id":"831263502","price":"1916.16","size":"0.001","time":"2026-07-30T15:17:27.040978Z","side":"BUY"},{"product_id":"ETH-USD","trade_id":"831263501","price":"1916.17","size":"0.00000434","time":"2026-07-30T15:17:27.040978Z","side":"BUY"},{"product_id":"ETH-USD","trade_id":"831263500","price":"1916.19","size":"0.00000514","time":"2026-07-30T15:17:27.040978Z","side":"BUY"},{"product_id":"ETH-USD","trade_id":"831263499","price":"1916.2","size":"0.0000049","time":"2026-07-30T15:17:27.040978Z","side":"BUY"},{"product_id":"ETH-USD","trade_id":"831263498","price":"1916.21","size":"0.00000467","time":"2026-07-30T15:17:27.040978Z","side":"BUY"},{"product_id":"ETH-USD","trade_id":"831263497","price":"1916.22","size":"0.00000447","time":"2026-07-30T15:17:27.040978Z","side":"BUY"},{"product_id":"ETH-USD","trade_id":"831263496","price":"1916.22","size":"0.00000439","time":"2026-07-30T15:17:27.040978Z","side":"BUY"},{"product_id":"ETH-USD","trade_id":"831263495","price":"1916.22","size":"0.00000439","time":"2026-07-30T15:17:27.040978Z","side":"BUY"},{"product_id":"ETH-USD","trade_id":"831263494","price":"1916.23","size":"0.04755748","time":"2026-07-30T15:17:27.03659Z","side":"SELL"},{"product_id":"ETH-USD","trade_id":"831263493","price":"1916.23","size":"0.00265338","time":"2026-07-30T15:17:27.03659Z","side":"SELL"},{"product_id":"ETH-USD","trade_id":"831263492","price":"1916.23","size":"0.00000599","time":"2026-07-30T15:17:27.03659Z","side":"SELL"},{"product_id":"ETH-USD","trade_id":"831263491","price":"1916.41","size":"0.04081102","time":"2026-07-30T15:17:21.314489Z","side":"SELL"},{"product_id":"ETH-USD","trade_id":"831263490","price":"1916.33","size":"0.00013936","time":"2026-07-30T15:17:21.314489Z","side":"SELL"},{"product_id":"ETH-USD","trade_id":"831263489","price":"1916.65","size":"0.25695461","time":"2026-07-30T15:17:21.166494Z","side":"SELL"}]}]}
{"channel":"subscriptions","timestamp":"2026-07-30T15:17:56.316262087Z","sequence_num":18,"events":[{"subscriptions":{"level2":["BTC-USD","ETH-USD"],"market_trades":["BTC-USD","ETH-USD"]}}]}
{"channel":"subscriptions","timestamp":"2026-07-30T15:17:56.316292109Z","sequence_num":19,"events":[{"subscriptions":{"heartbeats":["heartbeats"],"level2":["ETH-USD","BTC-USD"],"market_trades":["BTC-USD","ETH-USD"]}}]}
{"channel":"l2_data","timestamp":"2026-07-30T15:17:56.31692328Z","sequence_num":20,"events":[{"type":"update","product_id":"ETH-USD","updates":[{"side":"bid","event_time":"2026-07-30T15:17:56.065089Z","price_level":"1914.68","new_quantity":"0"},{"side":"bid","event_time":"2026-07-30T15:17:56.065089Z","price_level":"1914.62","new_quantity":"3.60223349"},{"side":"bid","event_time":"2026-07-30T15:17:56.065089Z","price_level":"1913.88","new_quantity":"18.0348269"},{"side":"bid","event_time":"2026-07-30T15:17:56.065089Z","price_level":"1913.69","new_quantity":"0"},{"side":"bid","event_time":"2026-07-30T15:17:56.065089Z","price_level":"1912.47","new_quantity":"43.84626971"},{"side":"bid","event_time":"2026-07-30T15:17:56.065089Z","price_level":"1912.33","new_quantity":"0"},{"side":"bid","event_time":"2026-07-30T15:17:56.065089Z","price_level":"1676.01","new_quantity":"0.05955624"},{"side":"offer","event_time":"2026-07-30T15:17:56.065089Z","price_level":"1916.43","new_quantity":"1.5375"},{"side":"offer","event_time":"2026-07-30T15:17:56.065089Z","price_level":"1916.48","new_quantity":"1.30515706"}]}]}
{"channel":"l2_data","timestamp":"2026-07-30T15:17:56.539175773Z","sequence_num":21,"events":[{"type":"update","product_id":"ETH-USD","updates":[{"side":"bid","event_time":"2026-07-30T15:17:56.146984Z","price_level":"1912.36","new_quantity":"3.01307393"},{"side":"bid","event_time":"2026-07-30T15:17:56.146984Z","price_level":"1676.01","new_quantity":"0"},{"side":"offer","event_time":"2026-07-30T15:17:56.146984Z","price_level":"1915.64","new_quantity":"0"},{"side":"offer","event_time":"2026-07-30T15:17:56.146984Z","price_level":"1918.11","new_quantity":"2.13234639"}]}]}
{"channel":"l2_data","timestamp":"2026-07-30T15:17:56.540429426Z","sequence_num":22,"events":[{"type":"update","product_id":"ETH-USD","updates":[{"side":"bid","event_time":"2026-07-30T15:17:56.196033Z","price_level":"1914.45","new_quantity":"0.01990162"},{"side":"bid","event_time":"2026-07-30T15:17:56.196033Z","price_level":"1912.49","new_quantity":"43.84581118"},{"side":"bid","event_time":"2026-07-30T15:17:56.196033Z","price_level":"1912.47","new_quantity":"0"},{"side":"offer","event_time":"2026-07-30T15:17:56.196033Z","price_level":"1915.45","new_quantity":"2.45"},{"side":"offer","event_time":"2026-07-30T15:17:56.196033Z","price_level":"1915.64","new_quantity":"1.04490479"}]}]}
{"channel":"l2_data","timestamp":"2026-07-30T15:17:56.541580378Z","sequence_num":23,"events":[{"type":"update","product_id":"ETH-USD","updates":[{"side":"bid","event_time":"2026-07-30T15:17:56.263619Z","price_level":"1915.35","new_quantity":"0"},{"side":"bid","event_time":"2026-07-30T15:17:56.263619Z","price_level":"1914.85","new_quantity":"0.58999189"},{"side":"bid","event_time":"2026-07-30T15:17:56.263619Z","price_level":"1914.75","new_quantity":"0.00723096"},{"side":"bid","event_time":"2026-07-30T15:17:56.263619Z","price_level":"1914.6","new_quantity":"0.051"},{"side":"bid","event_time":"2026-07-30T15:17:56.263619Z","price_level":"1914.5","new_quantity":"11.54404789"},{"side":"bid","event_time":"2026-07-30T15:17:56.263619Z","price_level":"1914.25","new_quantity":"0"},{"side":"offer","event_time":"2026-07-30T15:17:56.263619Z","price_level":"1915.45","new_quantity":"2.42415764"},{"side":"offer","event_time":"2026-07-30T15:17:56.263619Z","price_level":"1940.15","new_quantity":"0.42249987"}]}]}
{"channel":"l2_data","timestamp":"2026-07-30T15:17:56.542280381Z","sequence_num":24,"events":[{"type":"update","product_id":"ETH-USD","updates":[{"side":"bid","event_time":"2026-07-30T15:17:56.327888Z","price_level":"1915.35","new_quantity":"1.04490479"},{"side":"bid","event_time":"2026-07-30T15:17:56.327888Z","price_level":"1915.29","new_quantity":"0.04951335"},{"side":"bid","event_time":"2026-07-30T15:17:56.327888Z","price_level":"1915.28","new_quantity":"1.04490479"},{"side":"bid","event_time":"2026-07-30T15:17:56.327888Z","price_level":"1914.9","new_quantity":"11.5375"}]}]}
{"channel":"l2_data","timestamp":"2026-07-30T15:17:56.543533891Z","sequence_num":25,"events":[{"type":"update","product_id":"ETH-USD","updates":[{"side":"bid","event_time":"2026-07-30T15:17:56.351621Z","price_level":"1676.01","new_quantity":"0.05955624"},{"side":"offer","event_time":"2026-07-30T15:17:56.351621Z","price_level":"1944.2","new_quantity":"0.001"}]}]}
{"channel":"l2_data","timestamp":"2026-07-30T15:17:56.544155054Z","sequence_num":26,"events":[{"type":"update","product_id":"ETH-USD","updates":[{"side":"bid","event_time":"2026-07-30T15:17:56.402608Z","price_level":"1913.9","new_quantity":"0.03573335"}]}]}
{"channel":"l2_data","timestamp":"2026-07-30T15:17:56.544590227Z","sequence_num":27,"events":[{"type":"update","product_id":"ETH-USD","updates":[{"side":"bid","event_time":"2026-07-30T15:17:56.448746Z","price_level":"1914.55","new_quantity":"23.3745308"},{"side":"bid","event_time":"2026-07-30T15:17:56.448746Z","price_level":"1676.01","new_quantity":"0"},{"side":"offer","event_time":"2026-07-30T15:17:56.448746Z","price_level":"1915.47","new_quantity":"0"}]}]}
{"channel":"l2_data","timestamp":"2026-07-30T15:17:56.545059363Z","sequence_num":28,"events":[{"type":"update","product_id":"ETH-USD","updates":[{"side":"bid","event_time":"2026-07-30T15:17:56.504567Z","price_level":"1886.7","new_quantity":"0.001"},{"side":"bid","event_time":"2026-07-30T15:17:56.504567Z","price_level":"1858.4","new_quantity":"0.00243542"},{"side":"offer","event_time":"2026-07-30T15:17:56.504567Z","price_level":"1917.24","new_quantity":"0.001"},{"side":"offer","event_time":"2026-07-30T15:17:56.504567Z","price_level":"1917.25","new_quantity":"0"}]}]}
{"channel":"market_trades","timestamp":"2026-07-30T15:17:56.553126653Z","sequence_num":29,"events":[{"type":"update","trades":[{"product_id":"BTC-USD","trade_id":"1064604827","price":"64651.67","size":"0.00000005","time":"2026-07-30T15:17:56.479098Z","side":"BUY"}]}]}
{"channel":"l2_data","timestamp":"2026-07-30T15:17:56.577358199Z","sequence_num":30,"events":[{"type":"update","product_id":"ETH-USD","updates":[{"side":"bid","event_time":"2026-07-30T15:17:56.558391Z","price_level":"1913.92","new_quantity":"0"}]}]}
{"channel":"heartbeats","timestamp":"2026-07-30T15:17:56.623720076Z","sequence_num":31,"events":[{"current_time":"2026-07-30 15:17:56.621901431 +0000 UTC m=+6734.282950251","heartbeat_counter":6734}]}
{"channel":"l2_data","timestamp":"2026-07-30T15:17:56.627359449Z","sequence_num":32,"events":[{"type":"update","product_id":"ETH-USD","updates":[{"side":"bid","event_time":"2026-07-30T15:17:56.585372Z","price_level":"1914.33","new_quantity":"0.05214947"},{"side":"bid","event_time":"2026-07-30T15:17:56.585372Z","price_level":"1914.31","new_quantity":"2.08980958"},{"side":"bid","event_time":"2026-07-30T15:17:56.585372Z","price_level":"1913.56","new_quantity":"1.39664734"},{"side":"bid","event_time":"2026-07-30T15:17:56.585372Z","price_level":"1913.54","new_quantity":"0"}]}]}
{"channel":"l2_data","timestamp":"2026-07-30T15:17:56.705646989Z","sequence_num":33,"events":[{"type":"update","product_id":"ETH-USD","updates":[{"side":"bid","event_time":"2026-07-30T15:17:56.650125Z","price_level":"1913.25","new_quantity":"3.0636"},{"side":"bid","event_time":"2026-07-30T15:17:56.650125Z","price_level":"1912.36","new_quantity":"0"},{"side":"bid","event_time":"2026-07-30T15:17:56.650125Z","price_level":"1676.01","new_quantity":"0.05955624"},{"side":"offer","event_time":"2026-07-30T15:17:56.650125Z","price_level":"1917.55","new_quantity":"3.797343"},{"side":"offer","event_time":"2026-07-30T15:17:56.650125Z","price_level":"1918.11","new_quantity":"1.5375"},{"side":"offer","event_time":"2026-07-30T15:17:56.650125Z","price_level":"1918.23","new_quantity":"0"}]}]}
{"channel":"l2_data","timestamp":"2026-07-30T15:17:56.738038098Z","sequence_num":34,"events":[{"type":"update","product_id":"BTC-USD","updates":[{"side":"bid","event_time":"2026-07-30T15:17:56.330375Z","price_level":"64651.67","new_quantity":"0.2563277"},{"side":"bid","event_time":"2026-07-30T15:17:56.330375Z","price_level":"64651.35","new_quantity":"0"},{"side":"bid","event_time":"2026-07-30T15:17:56.330375Z","price_level":"64488.8","new_quantity":"0.01"},{"side":"bid","event_time":"2026-07-30T15:17:56.330375Z","price_level":"64206.37","new_quantity":"0.00583"},{"side":"bid","event_time":"2026-07-30T15:17:56.330375Z","price_level":"64204.9","new_quantity":"0"},{"side":"offer","event_time":"2026-07-30T15:17:56.330375Z","price_level":"64662.15","new_quantity":"0"},{"side":"offer","event_time":"2026-07-30T15:17:56.330375Z","price_level":"64667.27","new_quantity":"0.00116006"},{"side":"offer","event_time":"2026-07-30T15:17:56.330375Z","price_level":"64668.94","new_quantity":"0.6512973"},{"side":"offer","event_time":"2026-07-30T15:17:56.330375Z","price_level":"64668.95","new_quantity":"0.6512973"},{"side":"offer","event_time":"2026-07-30T15:17:56.330375Z","price_level":"64668.96","new_quantity":"0"},{"side":"offer","event_time":"2026-07-30T15:17:56.330375Z","price_level":"64668.97","new_quantity":"0"},{"side":"offer","event_time":"2026-07-30T15:17:56.330375Z","price_level":"64668.98","new_quantity":"0"},{"side":"offer","event_time":"2026-07-30T15:17:56.330375Z","price_level":"64668.99","new_quantity":"0"},{"side":"offer","event_time":"2026-07-30T15:17:56.330375Z","price_level":"64670.99","new_quantity":"0.1803432"},{"side":"offer","event_time":"2026-07-30T15:17:56.330375Z","price_level":"64671.99","new_quantity":"0"},{"side":"offer","event_time":"2026-07-30T15:17:56.330375Z","price_level":"64672.99","new_quantity":"0.32644783"}]}]}
{"channel":"l2_data","timestamp":"2026-07-30T15:17:56.741832445Z","sequence_num":35,"events":[{"type":"update","product_id":"BTC-USD","updates":[{"side":"bid","event_time":"2026-07-30T15:17:56.387915Z","price_level":"64646.82","new_quantity":"0.01546866"},{"side":"bid","event_time":"2026-07-30T15:17:56.387915Z","price_level":"56570.22","new_quantity":"0.00088297"},{"side":"offer","event_time":"2026-07-30T15:17:56.387915Z","price_level":"64660.23","new_quantity":"0.00009666"},{"side":"offer","event_time":"2026-07-30T15:17:56.387915Z","price_level":"64661.2","new_quantity":"0.00773261"},{"side":"offer","event_time":"2026-07-30T15:17:56.387915Z","price_level":"64668.94","new_quantity":"0"},{"side":"offer","event_time":"2026-07-30T15:17:56.387915Z","price_level":"64668.95","new_quantity":"0.32564865"},{"side":"offer","event_time":"2026-07-30T15:17:56.387915Z","price_level":"64670.99","new_quantity":"0"},{"side":"offer","event_time":"2026-07-30T15:17:56.387915Z","price_level":"64671.99","new_quantity":"0.1803432"}]}]}
{"channel":"l2_data","timestamp":"2026-07-30T15:17:56.743190842Z","sequence_num":36,"events":[{"type":"update","product_id":"BTC-USD","updates":[{"side":"bid","event_time":"2026-07-30T15:17:56.440622Z","price_level":"64635.87","new_quantity":"0"},{"side":"bid","event_time":"2026-07-30T15:17:56.440622Z","price_level":"64603.69","new_quantity":"0.893445"},{"side":"bid","event_time":"2026-07-30T15:17:56.440622Z","price_level":"64603.68","new_quantity":"2.18378196"},{"side":"bid","event_time":"2026-07-30T15:17:56.440622Z","price_level":"64603.67","new_quantity":"0"},{"side":"bid","event_time":"2026-07-30T15:17:56.440622Z","price_level":"64603.66","new_quantity":"0"},{"side":"bid","event_time":"2026-07-30T15:17:56.440622Z","price_level":"56570.22","new_quantity":"0.01324455"},{"side":"offer","event_time":"2026-07-30T15:17:56.440622Z","price_level":"64671.99","new_quantity":"0"},{"side":"offer","event_time":"2026-07-30T15:17:56.440622Z","price_level":"64672.99","new_quantity":"0.50679103"},{"side":"offer","event_time":"2026-07-30T15:17:56.440622Z","price_level":"64688.19","new_quantity":"0"}]}]}
{"channel":"l2_data","timestamp":"2026-07-30T15:17:56.744970103Z","sequence_num":37,"events":[{"type":"update","product_id":"BTC-USD","updates":[{"side":"bid","event_time":"2026-07-30T15:17:56.48638Z","price_level":"64651.67","new_quantity":"0.25632765"},{"side":"offer","event_time":"2026-07-30T15:17:56.48638Z","price_level":"64668.91","new_quantity":"0.6512973"},{"side":"offer","event_time":"2026-07-30T15:17:56.48638Z","price_level":"64668.92","new_quantity":"0"},{"side":"offer","event_time":"2026-07-30T15:17:56.48638Z","price_level":"64668.93","new_quantity":"0"},{"side":"offer","event_time":"2026-07-30T15:17:56.48638Z","price_level":"64668.94","new_quantity":"0"},{"side":"offer","event_time":"2026-07-30T15:17:56.48638Z","price_level":"64671.99","new_quantity":"0.1803432"},{"side":"offer","event_time":"2026-07-30T15:17:56.48638Z","price_level":"64672.99","new_quantity":"0.32644783"}]}]}
{"channel":"l2_data","timestamp":"2026-07-30T15:17:56.746658662Z","sequence_num":38,"events":[{"type":"update","product_id":"BTC-USD","updates":[{"side":"bid","event_time":"2026-07-30T15:17:56.534329Z","price_level":"64645.2","new_quantity":"0.01546906"},{"side":"bid","event_time":"2026-07-30T15:17:56.534329Z","price_level":"64603.71","new_quantity":"0.89344472"},{"side":"bid","event_time":"2026-07-30T15:17:56.534329Z","price_level":"64603.7","new_quantity":"2.18378128"},{"side":"bid","event_time":"2026-07-30T15:17:56.534329Z","price_level":"64603.69","new_quantity":"0"},{"side":"bid","event_time":"2026-07-30T15:17:56.534329Z","price_level":"64603.68","new_quantity":"0"},{"side":"bid","event_time":"2026-07-30T15:17:56.534329Z","price_level":"56570.22","new_quantity":"0"},{"side":"offer","event_time":"2026-07-30T15:17:56.534329Z","price_level":"64661.47","new_quantity":"0.00009666"},{"side":"offer","event_time":"2026-07-30T15:17:56.534329Z","price_level":"64662.76","new_quantity":"0.00773243"},{"side":"offer","event_time":"2026-07-30T15:17:56.534329Z","price_level":"64668.91","new_quantity":"0"},{"side":"offer","event_time":"2026-07-30T15:17:56.534329Z","price_level":"64671.99","new_quantity":"0"},{"side":"offer","event_time":"2026-07-30T15:17:56.534329Z","price_level":"64672.98","new_quantity":"0.1803432"}]}]}
{"channel":"l2_data","timestamp":"2026-07-30T15:17:56.747842022Z","sequence_num":39,"events":[{"type":"update","product_id":"BTC-USD","updates":[{"side":"bid","event_time":"2026-07-30T15:17:56.639651Z","price_level":"64645.2","new_quantity":"0.00773453"},{"side":"bid","event_time":"2026-07-30T15:17:56.639651Z","price_level":"64603.73","new_quantity":"0.89344445"},{"side":"bid","event_time":"2026-07-30T15:17:56.639651Z","price_level":"64603.72","new_quantity":"2.18378061"},{"side":"bid","event_time":"2026-07-30T15:17:56.639651Z","price_level":"64603.71","new_quantity":"0"},{"side":"bid","event_time":"2026-07-30T15:17:56.639651Z","price_level":"64603.7","new_quantity":"0"},{"side":"offer","event_time":"2026-07-30T15:17:56.639651Z","price_level":"64662.95","new_quantity":"0"},{"side":"offer","event_time":"2026-07-30T15:17:56.639651Z","price_level":"64668.94","new_quantity":"0"},{"side":"offer","event_time":"2026-07-30T15:17:56.639651Z","price_level":"64671.99","new_quantity":"0"},{"side":"offer","event_time":"2026-07-30T15:17:56.639651Z","price_level":"64672.98","new_quantity":"0"},{"side":"offer","event_time":"2026-07-30T15:17:56.639651Z","price_level":"64672.99","new_quantity":"0.50679103"},{"side":"offer","event_time":"2026-07-30T15:17:56.639651Z","price_level":"64688.19","new_quantity":"0.15458542"}]}]}
