{"channel":"status","type":"update","data":[{"version":"2.0.10","system":"online","api_version":"v2","connection_id":11889334205336741495}]}
{"method":"subscribe","result":{"channel":"book","depth":100,"snapshot":true,"symbol":"BTC/USD"},"success":true,"time_in":"2026-07-30T15:17:56.732958Z","time_out":"2026-07-30T15:17:56.733005Z"}
{"method":"subscribe","result":{"channel":"book","depth":100,"snapshot":true,"symbol":"ETH/USD"},"success":true,"time_in":"2026-07-30T15:17:56.732958Z","time_out":"2026-07-30T15:17:56.733005Z"}
{"method":"subscribe","result":{"channel":"trade","snapshot":false,"symbol":"BTC/USD"},"success":true,"time_in":"2026-07-30T15:17:56.733029Z","time_out":"2026-07-30T15:17:56.733041Z"}
{"method":"subscribe","result":{"channel":"trade","snapshot":false,"symbol":"ETH/USD"},"success":true,"time_in":"2026-07-30T15:17:56.733029Z","time_out":"2026-07-30T15:17:56.733041Z"}
{"channel":"book","type":"snapshot","data":[{"symbol":"BTC/USD","bids":[{"price":64654.6,"qty":0.01638667},{"price":64653.8,"qty":0.00005100},{"price":64652.8,"qty":0.01573073},{"price":64650.7,"qty":0.02943338},{"price":64650.6,"qty":0.00005100},{"price":64649.0,"qty":0.23199165},{"price":64648.8,"qty":0.77340865},{"price":64648.4,"qty":0.00755708},{"price":64647.4,"qty":0.00005100},{"price":64647.1,"qty":0.23199165},{"price":64646.7,"qty":0.77343405},{"price":64644.1,"qty":0.23093082},{"price":64644.0,"qty":0.81987474},{"price":64642.8,"qty":0.02062575},{"price":64641.9,"qty":0.06750000},{"price":64641.0,"qty":0.00154701},{"price":64640.9,"qty":0.00005100},{"price":64640.3,"qty":0.00154700},{"price":64639.8,"qty":0.67404184},{"price":64639.7,"qty":0.10425421},{"price":64638.0,"qty":0.04795941},{"price":64637.7,"qty":2.32062634},{"price":64636.9,"qty":0.11000000},{"price":64635.6,"qty":0.00050000},{"price":64635.2,"qty":0.00015300},{"price":64635.0,"qty":0.00154715},{"price":64632.2,"qty":0.04640931},{"price":64632.0,"qty":0.04641664},{"price":64631.9,"qty":0.49263900},{"price":64631.0,"qty":0.05928031},{"price":64630.9,"qty":0.06750000},{"price":64630.5,"qty":0.13109402},{"price":64630.3,"qty":0.03093932},{"price":64629.7,"qty":0.07734830},{"price":64629.0,"qty":0.09671733},{"price":64627.8,"qty":7.73659952},{"price":64627.7,"qty":0.40000000},{"price":64627.1,"qty":0.03788590},{"price":64626.0,"qty":0.04642095},{"price":64624.1,"qty":0.06750000},{"price":64623.7,"qty":0.01871294},{"price":64622.5,"qty":0.16625343},{"price":64622.0,"qty":0.23769319},{"price":64620.0,"qty":2.24699604},{"price":64619.9,"qty":7.73755192},{"price":64619.7,"qty":0.03411307},{"price":64619.6,"qty":0.00038687},{"price":64617.8,"qty":0.68952900},{"price":64617.2,"qty":0.86577500},{"price":64616.9,"qty":0.00727710},{"price":64616.4,"qty":0.07062398},{"price":64615.6,"qty":0.00062285},{"price":64615.5,"qty":0.28000000},{"price":64614.9,"qty":0.00005100},{"price":64614.7,"qty":0.06750000},{"price":64613.0,"qty":0.10643220},{"price":64612.5,"qty":0.00805135},{"price":64611.9,"qty":2.30994730},{"price":64611.8,"qty":7.73851693},{"price":64610.9,"qty":0.28534370},{"price":64610.3,"qty":0.00806822},{"price":64609.5,"qty":0.67060800},{"price":64609.4,"qty":0.15470000},{"price":64608.1,"qty":2.06298241},{"price":64605.5,"qty":0.23210000},{"price":64605.4,"qty":0.68831000},{"price":64604.4,"qty":0.06750000},{"price":64603.5,"qty":7.73950940},{"price":64602.4,"qty":0.35798000},{"price":64602.0,"qty":0.00005100},{"price":64601.2,"qty":0.58780000},{"price":64599.2,"qty":0.00154800},{"price":64598.8,"qty":0.00075394},{"price":64597.9,"qty":0.06750000},{"price":64596.7,"qty":2.89791647},{"price":64596.6,"qty":1.75968855},{"price":64596.5,"qty":7.74035326},{"price":64592.6,"qty":15.00000000},{"price":64591.9,"qty":0.04033045},{"price":64591.4,"qty":0.06750000},{"price":64590.9,"qty":0.32265130},{"price":64589.0,"qty":0.00005100},{"price":64588.3,"qty":0.54091800},{"price":64584.9,"qty":0.06750000},{"price":64584.5,"qty":5.41925675},{"price":64583.8,"qty":0.07140625},{"price":64581.1,"qty":0.02137188},{"price":64581.0,"qty":0.07004958},{"price":64580.0,"qty":0.00075942},{"price":64579.4,"qty":0.00154800},{"price":64578.4,"qty":0.06750000},{"price":64573.4,"qty":0.00200000},{"price":64572.7,"qty":0.01151640},{"price":64572.0,"qty":2.06571337},{"price":64571.9,"qty":5.48781280},{"price":64571.1,"qty":0.00664958},{"price":64571.0,"qty":1.50000000},{"price":64567.8,"qty":0.00517864},{"price":64567.7,"qty":0.01900000},{"price":64565.4,"qty":0.06750000}],"asks":[{"price":64654.7,"qty":0.21775205},{"price":64655.1,"qty":0.35083256},{"price":64655.2,"qty":0.77333415},{"price":64655.6,"qty":0.00193332},{"price":64657.0,"qty":0.40005100},{"price":64659.8,"qty":0.03346604},{"price":64660.1,"qty":0.01000000},{"price":64660.2,"qty":0.00005100},{"price":64661.4,"qty":2.84630212},{"price":64661.5,"qty":0.77325775},{"price":64661.9,"qty":0.49467200},{"price":64662.0,"qty":0.04639511},{"price":64662.3,"qty":0.07084485},{"price":64662.4,"qty":0.09217595},{"price":64663.1,"qty":0.02016397},{"price":64663.2,"qty":0.06750000},{"price":64663.5,"qty":0.00005100},{"price":64665.4,"qty":0.04579161},{"price":64666.6,"qty":0.05733994},{"price":64666.7,"qty":0.00005100},{"price":64667.9,"qty":0.14565180},{"price":64668.0,"qty":0.04639080},{"price":64668.7,"qty":0.00170382},{"price":64668.8,"qty":0.64527163},{"price":64669.0,"qty":2.31950454},{"price":64669.1,"qty":0.44881417},{"price":64669.9,"qty":0.00154600},{"price":64670.7,"qty":1.64373886},{"price":64671.5,"qty":0.06750000},{"price":64674.0,"qty":0.04638650},{"price":64674.1,"qty":0.00123800},{"price":64675.1,"qty":0.16789118},{"price":64675.7,"qty":0.00038581},{"price":64676.5,"qty":0.00097854},{"price":64677.4,"qty":0.00545740},{"price":64678.0,"qty":0.23769319},{"price":64678.9,"qty":1.93229551},{"price":64679.0,"qty":0.00772648},{"price":64679.2,"qty":0.06933493},{"price":64679.6,"qty":7.73041478},{"price":64680.0,"qty":0.04638219},{"price":64680.7,"qty":0.02057681},{"price":64681.4,"qty":0.06750000},{"price":64684.6,"qty":0.00154500},{"price":64687.1,"qty":0.00122141},{"price":64687.2,"qty":0.00100000},{"price":64687.6,"qty":10.76318963},{"price":64687.8,"qty":0.31331255},{"price":64688.9,"qty":0.01546911},{"price":64692.7,"qty":0.00005100},{"price":64692.9,"qty":0.06750000},{"price":64694.7,"qty":0.07432208},{"price":64694.8,"qty":0.01546911},{"price":64695.7,"qty":2.55452842},{"price":64695.8,"qty":7.72848212},{"price":64695.9,"qty":0.03081969},{"price":64696.4,"qty":7.72841158},{"price":64696.7,"qty":0.38477301},{"price":64696.8,"qty":0.10619176},{"price":64696.9,"qty":1.08581706},{"price":64697.0,"qty":0.00151058},{"price":64699.4,"qty":0.06904500},{"price":64699.9,"qty":0.06946847},{"price":64702.3,"qty":0.03094000},{"price":64704.4,"qty":7.72745989},{"price":64705.6,"qty":0.00005100},{"price":64705.9,"qty":0.06750000},{"price":64706.3,"qty":0.23210000},{"price":64706.9,"qty":0.01571388},{"price":64707.3,"qty":0.00806397},{"price":64711.3,"qty":5.40863935},{"price":64711.6,"qty":0.06889619},{"price":64712.4,"qty":0.06750000},{"price":64712.8,"qty":0.06985535},{"price":64713.8,"qty":0.70182000},{"price":64714.2,"qty":0.00154500},{"price":64714.4,"qty":15.00000000},{"price":64715.4,"qty":5.40829953},{"price":64716.0,"qty":0.01995527},{"price":64716.4,"qty":0.07753156},{"price":64718.4,"qty":0.01546911},{"price":64718.6,"qty":0.00005100},{"price":64718.9,"qty":0.06750000},{"price":64719.7,"qty":0.54111900},{"price":64725.4,"qty":0.17319176},{"price":64726.4,"qty":1.89206988},{"price":64728.9,"qty":0.00154400},{"price":64729.7,"qty":0.00804736},{"price":64730.4,"qty":0.20626516},{"price":64730.5,"qty":0.60000000},{"price":64731.8,"qty":0.00255344},{"price":64731.9,"qty":0.06750000},{"price":64735.4,"qty":0.00046082},{"price":64735.5,"qty":0.54109300},{"price":64738.4,"qty":0.06750000},{"price":64738.9,"qty":0.01000000},{"price":64739.2,"qty":0.04032656},{"price":64740.6,"qty":0.00917018},{"price":64741.1,"qty":2.02574559},{"price":64741.2,"qty":1.38030000}],"checksum":2464649704,"timestamp":"2026-07-30T15:17:56.980075Z"}]}
{"channel":"book","type":"update","data":[{"symbol":"BTC/USD","bids":[],"asks":[{"price":64655.6,"qty":0.00000000},{"price":64741.5,"qty":5.40611738}],"checksum":4065922266,"timestamp":"2026-07-30T15:17:57.035409Z"}]}
{"channel":"book","type":"update","data":[{"symbol":"BTC/USD","bids":[],"asks":[{"price":64654.7,"qty":0.21968539}],"checksum":3322534944,"timestamp":"2026-07-30T15:17:57.036895Z"}]}
{"channel":"book","type":"update","data":[{"symbol":"BTC/USD","bids":[],"asks":[{"price":64656.0,"qty":0.01630044}],"checksum":2958905020,"timestamp":"2026-07-30T15:17:57.036970Z"}]}
{"channel":"book","type":"update","data":[{"symbol":"BTC/USD","bids":[],"asks":[{"price":64661.4,"qty":0.00000000},{"price":64741.5,"qty":5.40611738},{"price":64666.1,"qty":2.84630212}],"checksum":3670320419,"timestamp":"2026-07-30T15:17:57.093298Z"}]}
{"channel":"book","type":"update","data":[{"symbol":"BTC/USD","bids":[],"asks":[{"price":64661.4,"qty":0.44098768}],"checksum":2317771365,"timestamp":"2026-07-30T15:17:57.094680Z"}]}
{"channel":"book","type":"update","data":[{"symbol":"BTC/USD","bids":[],"asks":[{"price":64668.7,"qty":0.00000000},{"price":64741.2,"qty":1.38030000},{"price":64666.0,"qty":0.00170382}],"checksum":2317771365,"timestamp":"2026-07-30T15:17:57.097860Z"}]}
{"channel":"book","type":"update","data":[{"symbol":"BTC/USD","bids":[],"asks":[{"price":64667.9,"qty":0.00000000},{"price":64741.2,"qty":1.38030000},{"price":64666.0,"qty":0.14735562}],"checksum":2317771365,"timestamp":"2026-07-30T15:17:57.098906Z"}]}
{"channel":"book","type":"update","data":[{"symbol":"BTC/USD","bids":[],"asks":[{"price":64666.6,"qty":0.00000000},{"price":64741.5,"qty":5.40611738}],"checksum":2317771365,"timestamp":"2026-07-30T15:17:57.099376Z"}]}
{"channel":"book","type":"update","data":[{"symbol":"BTC/USD","bids":[{"price":64648.8,"qty":0.00000000},{"price":64564.2,"qty":0.10352607}],"asks":[],"checksum":144543480,"timestamp":"2026-07-30T15:17:57.100672Z"}]}
{"channel":"book","type":"update","data":[{"symbol":"BTC/USD","bids":[],"asks":[{"price":64666.0,"qty":1.01083968}],"checksum":144543480,"timestamp":"2026-07-30T15:17:57.101073Z"}]}
{"channel":"book","type":"update","data":[{"symbol":"BTC/USD","bids":[{"price":64649.6,"qty":0.77339970}],"asks":[],"checksum":3646838342,"timestamp":"2026-07-30T15:17:57.102059Z"}]}
{"channel":"book","type":"update","data":[{"symbol":"BTC/USD","bids":[],"asks":[{"price":64670.7,"qty":0.09699626},{"price":64675.0,"qty":1.54677068}],"checksum":3646838342,"timestamp":"2026-07-30T15:17:57.132505Z"}]}
{"channel":"book","type":"update","data":[{"symbol":"BTC/USD","bids":[{"price":64646.7,"qty":0.00000000},{"price":64564.2,"qty":0.10352607}],"asks":[],"checksum":3646838342,"timestamp":"2026-07-30T15:17:57.142193Z"}]}
{"channel":"book","type":"update","data":[{"symbol":"BTC/USD","bids":[{"price":64649.6,"qty":0.00000000},{"price":64560.2,"qty":0.02488101}],"asks":[],"checksum":3966569552,"timestamp":"2026-07-30T15:17:57.554902Z"}]}
{"channel":"book","type":"update","data":[{"symbol":"BTC/USD","bids":[],"asks":[{"price":64656.8,"qty":0.77331399}],"checksum":2791029543,"timestamp":"2026-07-30T15:17:57.556495Z"}]}
{"channel":"book","type":"update","data":[{"symbol":"BTC/USD","bids":[{"price":64648.8,"qty":0.77340839}],"asks":[],"checksum":2765958778,"timestamp":"2026-07-30T15:17:57.556801Z"}]}
{"channel":"book","type":"update","data":[{"symbol":"BTC/USD","bids":[{"price":64646.7,"qty":0.77343380}],"asks":[],"checksum":2765958778,"timestamp":"2026-07-30T15:17:57.557143Z"}]}
{"channel":"book","type":"update","data":[{"symbol":"BTC/USD","bids":[],"asks":[{"price":64675.0,"qty":0.00000000},{"price":64741.2,"qty":1.38030000},{"price":64669.0,"qty":3.86626419}],"checksum":2765958778,"timestamp":"2026-07-30T15:17:57.702440Z"}]}
{"channel":"book","type":"update","data":[{"symbol":"BTC/USD","bids":[],"asks":[{"price":64669.0,"qty":2.31950454},{"price":64675.0,"qty":1.54673995}],"checksum":2765958778,"timestamp":"2026-07-30T15:17:57.719755Z"}]}
{"channel":"book","type":"update","data":[{"symbol":"BTC/USD","bids":[],"asks":[{"price":64654.7,"qty":0.01968539}],"checksum":4291975572,"timestamp":"2026-07-30T15:17:57.838776Z"}]}
{"channel":"book","type":"update","data":[{"symbol":"BTC/USD","bids":[{"price":64654.6,"qty":0.04688667}],"asks":[],"checksum":935732163,"timestamp":"2026-07-30T15:17:57.840843Z"}]}
{"channel":"book","type":"update","data":[{"symbol":"BTC/USD","bids":[],"asks":[{"price":64654.7,"qty":0.21968539}],"checksum":1825133613,"timestamp":"2026-07-30T15:17:57.845994Z"}]}
{"channel":"book","type":"update","data":[{"symbol":"BTC/USD","bids":[{"price":64654.6,"qty":0.01638667}],"asks":[],"checksum":2765958778,"timestamp":"2026-07-30T15:17:57.847749Z"}]}
{"channel":"book","type":"update","data":[{"symbol":"BTC/USD","bids":[],"asks":[{"price":64654.7,"qty":0.01968539}],"checksum":4291975572,"timestamp":"2026-07-30T15:17:57.850171Z"}]}
{"channel":"book","type":"update","data":[{"symbol":"BTC/USD","bids":[{"price":64654.6,"qty":0.04688667}],"asks":[],"checksum":935732163,"timestamp":"2026-07-30T15:17:57.851919Z"}]}
{"channel":"book","type":"update","data":[{"symbol":"BTC/USD","bids":[],"asks":[{"price":64654.7,"qty":0.21968539}],"checksum":1825133613,"timestamp":"2026-07-30T15:17:57.854534Z"}]}
{"channel":"book","type":"update","data":[{"symbol":"BTC/USD","bids":[{"price":64654.6,"qty":0.01638667}],"asks":[],"checksum":2765958778,"timestamp":"2026-07-30T15:17:57.855950Z"}]}
{"channel":"book","type":"update","data":[{"symbol":"BTC/USD","bids":[],"asks":[{"price":64667.7,"qty":1.08581706}],"checksum":2765958778,"timestamp":"2026-07-30T15:17:58.016809Z"}]}
{"channel":"book","type":"update","data":[{"symbol":"BTC/USD","bids":[{"price":64653.8,"qty":0.01578173}],"asks":[],"checksum":2304616744,"timestamp":"2026-07-30T15:17:58.090564Z"}]}
{"channel":"book","type":"update","data":[{"symbol":"BTC/USD","bids":[],"asks":[{"price":64656.0,"qty":0.00000000},{"price":64741.1,"qty":2.02574559}],"checksum":2699478463,"timestamp":"2026-07-30T15:17:58.090603Z"}]}
{"channel":"book","type":"update","data":[{"symbol":"BTC/USD","bids":[{"price":64652.8,"qty":0.00000000},{"price":64564.2,"qty":0.10352607}],"asks":[],"checksum":911114762,"timestamp":"2026-07-30T15:17:58.090874Z"}]}
{"channel":"book","type":"update","data":[{"symbol":"BTC/USD","bids":[],"asks":[{"price":64657.0,"qty":0.41635144}],"checksum":2289980396,"timestamp":"2026-07-30T15:17:58.092402Z"}]}
{"channel":"book","type":"update","data":[{"symbol":"BTC/USD","bids":[{"price":64629.7,"qty":0.00000000},{"price":64560.2,"qty":0.02488101},{"price":64630.3,"qty":0.07734914}],"asks":[],"checksum":2289980396,"timestamp":"2026-07-30T15:17:58.111513Z"}]}
{"channel":"book","type":"update","data":[{"symbol":"BTC/USD","bids":[{"price":64632.0,"qty":0.07735629}],"asks":[],"checksum":2289980396,"timestamp":"2026-07-30T15:17:58.115002Z"}]}
{"channel":"book","type":"update","data":[{"symbol":"BTC/USD","bids":[{"price":64648.8,"qty":0.00000000},{"price":64559.6,"qty":0.00154800}],"asks":[],"checksum":2437430129,"timestamp":"2026-07-30T15:17:58.196173Z"}]}
{"channel":"book","type":"update","data":[{"symbol":"BTC/USD","bids":[],"asks":[{"price":64656.8,"qty":0.00000000},{"price":64741.2,"qty":1.38030000}],"checksum":4142813312,"timestamp":"2026-07-30T15:17:58.197487Z"}]}
{"channel":"book","type":"update","data":[{"symbol":"BTC/USD","bids":[{"price":64646.7,"qty":0.00000000},{"price":64559.0,"qty":2.06340105}],"asks":[],"checksum":355126725,"timestamp":"2026-07-30T15:17:58.197844Z"}]}
{"channel":"book","type":"update","data":[{"symbol":"BTC/USD","bids":[],"asks":[{"price":64657.9,"qty":0.77330187}],"checksum":2069487801,"timestamp":"2026-07-30T15:17:58.199552Z"}]}
{"channel":"book","type":"update","data":[{"symbol":"BTC/USD","bids":[{"price":64649.7,"qty":0.77339858}],"asks":[],"checksum":881279723,"timestamp":"2026-07-30T15:17:58.199803Z"}]}
{"channel":"book","type":"update","data":[{"symbol":"BTC/USD","bids":[{"price":64647.8,"qty":0.77342138}],"asks":[],"checksum":865015774,"timestamp":"2026-07-30T15:17:58.200032Z"}]}
{"channel":"book","type":"update","data":[{"symbol":"BTC/USD","bids":[],"asks":[{"price":64666.0,"qty":1.00913586},{"price":64661.3,"qty":0.00170382}],"checksum":3890804235,"timestamp":"2026-07-30T15:17:58.201220Z"}]}
{"channel":"book","type":"update","data":[{"symbol":"BTC/USD","bids":[],"asks":[{"price":64707.3,"qty":0.00000000},{"price":64741.1,"qty":2.02574559}],"checksum":3890804235,"timestamp":"2026-07-30T15:17:58.259648Z"}]}
{"channel":"book","type":"update","data":[{"symbol":"BTC/USD","bids":[],"asks":[{"price":64655.2,"qty":0.00000000},{"price":64741.2,"qty":1.38030000}],"checksum":3070493960,"timestamp":"2026-07-30T15:17:58.311769Z"}]}
{"channel":"book","type":"update","data":[{"symbol":"BTC/USD","bids":[{"price":64649.7,"qty":0.00000000},{"price":64559.6,"qty":0.00154800}],"asks":[],"checksum":116316162,"timestamp":"2026-07-30T15:17:58.311966Z"}]}
{"channel":"book","type":"update","data":[{"symbol":"BTC/USD","bids":[],"asks":[{"price":64656.1,"qty":0.77332297}],"checksum":2239953759,"timestamp":"2026-07-30T15:17:58.313511Z"}]}
{"channel":"book","type":"update","data":[{"symbol":"BTC/USD","bids":[{"price":64650.2,"qty":0.77339169}],"asks":[],"checksum":2154120482,"timestamp":"2026-07-30T15:17:58.313857Z"}]}
{"channel":"book","type":"update","data":[{"symbol":"BTC/USD","bids":[{"price":64650.2,"qty":0.00000000},{"price":64559.6,"qty":0.00154800}],"asks":[],"checksum":2239953759,"timestamp":"2026-07-30T15:17:58.328927Z"}]}
{"channel":"book","type":"update","data":[{"symbol":"BTC/USD","bids":[{"price":64653.8,"qty":0.00005100}],"asks":[],"checksum":3791795546,"timestamp":"2026-07-30T15:17:58.364087Z"}]}
{"channel":"book","type":"update","data":[{"symbol":"BTC/USD","bids":[{"price":64654.6,"qty":0.03211740}],"asks":[],"checksum":956679135,"timestamp":"2026-07-30T15:17:58.364168Z"}]}
{"channel":"book","type":"update","data":[{"symbol":"BTC/USD","bids":[],"asks":[{"price":64657.0,"qty":0.40005100}],"checksum":842898027,"timestamp":"2026-07-30T15:17:58.364197Z"}]}
{"channel":"book","type":"update","data":[{"symbol":"BTC/USD","bids":[{"price":64644.0,"qty":0.82142168}],"asks":[],"checksum":842898027,"timestamp":"2026-07-30T15:17:58.368946Z"}]}
{"channel":"book","type":"update","data":[{"symbol":"BTC/USD","bids":[],"asks":[{"price":64655.1,"qty":0.00000000},{"price":64741.2,"qty":1.38030000}],"checksum":2732382352,"timestamp":"2026-07-30T15:17:58.369019Z"}]}
{"channel":"book","type":"update","data":[{"symbol":"BTC/USD","bids":[],"asks":[{"price":64657.9,"qty":0.00000000},{"price":64741.5,"qty":5.40611738}],"checksum":1733735754,"timestamp":"2026-07-30T15:17:58.369518Z"}]}
{"channel":"book","type":"update","data":[{"symbol":"BTC/USD","bids":[],"asks":[{"price":64656.1,"qty":0.00000000},{"price":64743.7,"qty":0.00154400}],"checksum":19375270,"timestamp":"2026-07-30T15:17:58.369804Z"}]}
{"channel":"book","type":"update","data":[{"symbol":"BTC/USD","bids":[{"price":64647.8,"qty":0.00000000},{"price":64559.0,"qty":2.06340105}],"asks":[],"checksum":3253253257,"timestamp":"2026-07-30T15:17:58.369897Z"}]}
{"channel":"book","type":"update","data":[{"symbol":"BTC/USD","bids":[],"asks":[{"price":64666.0,"qty":0.86348406},{"price":64661.3,"qty":0.14735562}],"checksum":1404621514,"timestamp":"2026-07-30T15:17:58.371065Z"}]}
{"channel":"book","type":"update","data":[{"symbol":"BTC/USD","bids":[],"asks":[{"price":64661.5,"qty":0.00000000},{"price":64744.3,"qty":1.65907754}],"checksum":3758646620,"timestamp":"2026-07-30T15:17:58.371785Z"}]}
{"channel":"book","type":"update","data":[{"symbol":"BTC/USD","bids":[{"price":64644.0,"qty":0.04795496}],"asks":[],"checksum":18027469,"timestamp":"2026-07-30T15:17:58.371951Z"}]}
{"channel":"book","type":"update","data":[{"symbol":"BTC/USD","bids":[],"asks":[{"price":64654.7,"qty":0.01968539}],"checksum":3502956658,"timestamp":"2026-07-30T15:17:58.373565Z"}]}
{"channel":"book","type":"update","data":[{"symbol":"BTC/USD","bids":[],"asks":[{"price":64664.4,"qty":0.77322342}],"checksum":3502956658,"timestamp":"2026-07-30T15:17:58.373970Z"}]}
{"channel":"trade","type":"update","data":[{"symbol":"BTC/USD","side":"sell","price":64654.6,"qty":0.00024667,"ord_type":"limit","trade_id":104503106,"timestamp":"2026-07-30T15:17:59.036319Z"}]}
{"channel":"trade","type":"update","data":[{"symbol":"BTC/USD","side":"buy","price":64654.7,"qty":0.00022242,"ord_type":"limit","trade_id":104503107,"timestamp":"2026-07-30T15:18:03.250513Z"}]}
